Workbook

Sheet 일반BS
A3: 임직원 할인 판매 프로모션 합의서
A5: "본 합의서는 ㈜일룸 (이하 공급업자)과 | F5: 춘천3 | H5: (이하 대리점) 간에
A6: 다음과 같이 SK하이닉스 임직원 할인 판매 프로모션 관련 진행에 대하여 합의한다.
A9: - 다 음 -
B12: 제1조 [목적]
B13: 1) 이 합의는 SK하이닉스 임직원 할인판매 프로모션기간 중 분담금 협의 조건 등을 정함을 목적으로 한다.
B15: 제2조 [수수료 변경 품목]
B16: 1) 공급업자가 정한 일룸 전체 제품을 수수료 변경 품목으로 한다.
B17: 2) 공급품목은 운영 중 상호합의하에 조정할 수 있으며, 계약기간 중 공급품목의 변동은 없으나 불가피한 사유
B18: 발생 시 사전 통지 후 공급을 중단할 수 있다.
B20: 제3조 [판매수수료 및 미수금]
B21: 1) 본 프로모션에 대한 판매수수료율은 「2025년 위탁판매리점 판매수수료 및 지원금 약정서」에서 정한 판매수수료율을 동일하게 적용한다.
B22: 다만, 판매수수료 산정의 기준이 되는 금액은 정상 소비자가(VAT별도)에서 10%를 할인한 금액으로 한다.
B23: 2) 제1항의 10% 할인 금액(VAT 별도)에 대하여는 각 대리점과 본사가 각각 50%의 비율로 분담한다.
B24: 3) 전항에 따라 발생하는 대리점 부담분은 미수금으로 산정하여 위탁판매수수료(VAT 별도)정산 시 상계 처리하기로 한다.
B25: 상기 정산 방식에 대해 설명받고 이에 동의하였음을 상호간에 확인한다.
... B51: 그 변경 및 수정은 공급업자와 대리점이 해당 서면에 서명 또는 기명날인함과 동시에 그 효력을 발생한다.
H54: 46037
B57: "공급업자" | C57: 상호 : | D57: 주식회사 일룸 | E57: ( | F57: 215-86-93600 | G57: )
C58: 주소 : | D58: 서울특별시 송파구 오금동 45-1 퍼시스빌딩 3층
C59: 대표 : | D59: 정 보 은 | J59: (인)
B62: "대리점" | C62: 상호 : | D62: =VLOOKUP(F5,계약체결용!$B$2:$K$65,7,FALSE) -> 퍼시스춘천전시장 | E62: ( | F62: =VLOOKUP(F5,계약체결용!$B$2:$K$65,8,FALSE) -> 221-02-56686 | G62: )
C63: 주소 : | D63: =VLOOKUP(F5,계약체결용!$B$2:$K$65,10,FALSE) -> 강원 춘천시 동면 만천리 700번지
C64: 대표 : | D64: =VLOOKUP(F5,계약체결용!$B$2:$K$65,9,FALSE) -> 이 신 구 | J64: (인)

Sheet 롯데영등포_입점BS
A3: 임직원 할인판매 프로모션 합의서
A5: ="본 합의서는 ㈜일룸 (이하 공급업자)과 롯데영등포점 (이하 대리점) 간에" -> 본 합의서는 ㈜일룸 (이하 공급업자)과 롯데영등포점 (이하 대리점) 간에
A6: 다음과 같이 아모레퍼시픽 임직원할인 판매 프로모션 관련 진행에 대하여 합의한다.
A9: - 다 음 -
B12: 제1조 [목적]
B13: 1) 이 합의는 아모레퍼시픽 임직원 할인판매 프로모션기간 중 분담금 협의 조건 등을 정함을 목적으로 한다.
B15: 제2조 [수수료 변경 품목]
B16: 1) 공급업자가 정한 일룸 전체 제품을 수수료 변경 품목으로 한다.
B17: 2) 공급품목은 운영 중 상호합의하에 조정할 수 있으며, 계약기간 중 공급품목의 변동은 없으나 불가피한 사유
B18: 발생 시 사전 통지 후 공급을 중단할 수 있다.
B20: 제3조 [판매수수료]
B21: 1) 판매수수료는 10% 할인된 위탁판매금액(VAT별도)의 A타입 품목과 B타입 품목은 20.5% 책정되며, 공지와 자료를 통하여 해당
B22: 판매수수료 산정방식에 대해 오프라인 제품과 공급단가 및 판매관리비 등에 차이가 있어 수수료가 다름을 설명받고
B23: 이에 동의하였음을 상호간에 확인한다.
B25: 제4조 [프로모션 기간 및 상세내용]
B26: 1) 아모레퍼시픽 임직원 할인판매 프로모션은 일정 기간만 한정 진행되는 건을 대상으로 한다.
... B46: 그 변경 및 수정은 공급업자와 대리점이 해당 서면에 서명 또는 기명날인함과 동시에 그 효력을 발생한다.
G49: 45869
B52: "공급업자" | C52: 상호 : | D52: 주식회사 일룸 (215-86-93600)
C53: 주소 : | D53: 서울특별시 송파구 오금동 45-1 퍼시스빌딩 3층
C54: 대표 : | D54: 정 보 은 | H54: (인)
B57: "대리점" | C57: 상호 : | D57: 일룸 롯데영등포점 (113-22-86081)
C58: 주소 : | D58: 서울 영등포구 경인로 846 (영등포동, 영등포 민자역사)
C59: 대표 : | D59: 오 승 균 | H59: (인)

Sheet 투자B
A3: 임직원 할인판매 프로모션 합의서
A5: "본 합의서는 ㈜일룸 (이하 공급업자)과 | F5: 신세계파주2 | H5: (이하 대리점) 간에
A6: 다음과 같이 SK하이닉스 임직원할인 판매 프로모션 관련 진행에 대하여 합의한다.
A9: - 다 음 -
B12: 제1조 [목적]
B13: 1) 이 합의는 SK하이닉스 임직원 할인판매 프로모션기간 중 분담금 협의 조건 등을 정함을 목적으로 한다.
B15: 제2조 [수수료 변경 품목]
B16: 1) 공급업자가 정한 일룸 전체 제품을 수수료 변경 품목으로 한다.
B17: 2) 공급품목은 운영 중 상호합의하에 조정할 수 있으며, 계약기간 중 공급품목의 변동은 없으나 불가피한 사유
B18: 발생 시 사전 통지 후 공급을 중단할 수 있다.
B20: 제3조 [판매수수료 및 미수금]
B21: 1) 본 프로모션에 대한 판매수수료율은 「2025년 위탁판매리점 판매수수료 및 지원금 약정서」에서 정한 판매수수료율을 동일하게 적용한다.
B22: 다만, 판매수수료 산정의 기준이 되는 금액은 정상 소비자가(VAT별도)에서 10%를 할인한 금액으로 한다.
B23: 2) 제1항의 10% 할인 금액(VAT 별도)에 대하여는 각 대리점과 본사가 각각 40%(대리점), 60%(본사)의 비율로 분담한다.
B24: 3) 전항에 따라 발생하는 대리점 부담분은 미수금으로 산정하여 위탁판매수수료(VAT 별도)정산 시 상계 처리하기로 한다.
B25: 상기 정산 방식에 대해 설명받고 이에 동의하였음을 상호간에 확인한다.
... B51: 그 변경 및 수정은 공급업자와 대리점이 해당 서면에 서명 또는 기명날인함과 동시에 그 효력을 발생한다.
H54: 46037
B57: "공급업자" | C57: 상호 : | D57: 주식회사 일룸 | E57: ( | F57: 215-86-93600 | G57: )
C58: 주소 : | D58: 서울특별시 송파구 오금동 45-1 퍼시스빌딩 3층
C59: 대표 : | D59: 정 보 은 | J59: (인)
B62: "대리점" | C62: 상호 : | D62: =VLOOKUP(F5,계약체결용!$B$2:$K$65,7,FALSE) -> #N/A | E62: ( | F62: =VLOOKUP(F5,계약체결용!$B$2:$K$65,8,FALSE) -> #N/A | G62: )
C63: 주소 : | D63: =VLOOKUP(F5,계약체결용!$B$2:$K$65,10,FALSE) -> #N/A
C64: 대표 : | D64: =VLOOKUP(F5,계약체결용!$B$2:$K$65,9,FALSE) -> #N/A | J64: (인)

Sheet 입점BS
A3: 임직원 할인판매 프로모션 합의서
A5: "본 합의서는 ㈜일룸 (이하 공급업자)과 | F5: 롯데의왕 | H5: (이하 대리점) 간에
A6: 다음과 같이 SK하이닉스 임직원할인 판매 프로모션 관련 진행에 대하여 합의한다.
A9: - 다 음 -
B12: 제1조 [목적]
B13: 1) 이 합의는 SK하이닉스 임직원 할인판매 프로모션기간 중 분담금 협의 조건 등을 정함을 목적으로 한다.
B15: 제2조 [수수료 변경 품목]
B16: 1) 공급업자가 정한 일룸 전체 제품을 수수료 변경 품목으로 한다.
B17: 2) 공급품목은 운영 중 상호합의하에 조정할 수 있으며, 계약기간 중 공급품목의 변동은 없으나 불가피한 사유
B18: 발생 시 사전 통지 후 공급을 중단할 수 있다.
B20: 제3조 [판매수수료 및 미수금]
B21: 1) 본 프로모션에 대한 판매수수료율은 「2025년 위탁판매리점 판매수수료 및 지원금 약정서」에서 정한 판매수수료율을 동일하게 적용한다.
B22: 다만, 판매수수료 산정의 기준이 되는 금액은 정상 소비자가(VAT별도)에서 10%를 할인한 금액으로 한다.
B23: 2) 제1항의 10% 할인 금액(VAT 별도)에 대하여는 각 대리점과 본사가 각각 40%(대리점), 60%(본사)의 비율로 분담한다.
B24: 3) 전항에 따라 발생하는 대리점 부담분은 미수금으로 산정하여 위탁판매수수료(VAT 별도)정산 시 상계 처리하기로 한다.
B25: 상기 정산 방식에 대해 설명받고 이에 동의하였음을 상호간에 확인한다.
... B51: 그 변경 및 수정은 공급업자와 대리점이 해당 서면에 서명 또는 기명날인함과 동시에 그 효력을 발생한다.
H54: 46037
B57: "공급업자" | C57: 상호 : | D57: 주식회사 일룸 | E57: ( | F57: 215-86-93600 | G57: )
C58: 주소 : | D58: 서울특별시 송파구 오금동 45-1 퍼시스빌딩 3층
C59: 대표 : | D59: 정 보 은 | J59: (인)
B62: "대리점" | C62: 상호 : | D62: =VLOOKUP(F5,계약체결용!$B$2:$K$65,7,FALSE) -> #N/A | E62: ( | F62: =VLOOKUP(F5,계약체결용!$B$2:$K$65,8,FALSE) -> #N/A | G62: )
C63: 주소 : | D63: =VLOOKUP(F5,계약체결용!$B$2:$K$65,10,FALSE) -> #N/A
C64: 대표 : | D64: =VLOOKUP(F5,계약체결용!$B$2:$K$65,9,FALSE) -> #N/A | J64: (인)

Sheet 계약체결용
B2: 대리점명 | C2: 대리점유형 | D2: 25년 거래보증금 설정 | G2: 24거래보증금 | H2: 사업자명 | I2: 사업자번호 | J2: 대표 | K2: 주소
B3: 강릉4 | C3: =VLOOKUP(B3,'[1]2503기준유통망'!$B:$E,4,0) -> B/S-Shop | D3: 현금 | E3: 이천만원 | F3: 20,000,000원 | G3: =E3&" (\"&F3&")" -> 이천만원 (\20,000,000원) | H3: =VLOOKUP(B3,[1]계약체결용!$B:$K,7,0) -> 일룸강릉브랜드샵(주) | I3: =VLOOKUP(B3,[1]계약체결용!$B:$K,8,0) -> 201-86-45638 | J3: =VLOOKUP(B3,[1]계약체결용!$B:$K,9,0) -> 최 종 섭 | K3: =VLOOKUP(B3,[1]계약체결용!$B:$K,10,0) -> 강원 강릉시 율곡로 3190 | L3: 201-86-45638 | M3: =VLOOKUP(L3,'[2]25년계약체결용'!$I$2:$O$72,7,0) -> gniloom@daum.net
B4: 거제4 | C4: =VLOOKUP(B4,'[1]2503기준유통망'!$B:$E,4,0) -> B/S-Shop | D4: 현금 | E4: 이천만원 | F4: 20,000,000원 | G4: =E4&" (\"&F4&")" -> 이천만원 (\20,000,000원) | H4: 일룸 거제점 | I4: 178-73-00699 | J4: 안 율 | K4: 경상남도 거제시 수양로 454-40, 2층(수월동) | L4: 178-73-00699 | M4: ld5yul@daum.net
B5: 경주4 | C5: =VLOOKUP(B5,'[1]2503기준유통망'!$B:$E,4,0) -> B/S-Shop | D5: 현금 | E5: 이천만원 | F5: 20,000,000원 | G5: =E5&" (\"&F5&")" -> 이천만원 (\20,000,000원) | H5: =VLOOKUP(B5,[1]계약체결용!$B:$K,7,0) -> 그린퍼니처 | I5: =VLOOKUP(B5,[1]계약체결용!$B:$K,8,0) -> 505-09-65796 | J5: =VLOOKUP(B5,[1]계약체결용!$B:$K,9,0) -> 신 도 철 | K5: =VLOOKUP(B5,[1]계약체결용!$B:$K,10,0) -> 경북 경주시 원화로468, b동 | L5: 505-09-65796 | M5: =VLOOKUP(L5,'[2]25년계약체결용'!$I$2:$O$72,7,0) -> ch9000@hanmail.net
B6: 구미5 | C6: =VLOOKUP(B6,'[1]2503기준유통망'!$B:$E,4,0) -> B/S-Shop | D6: 현금 | E6: 이천만원 | F6: 20,000,000원 | G6: =E6&" (\"&F6&")" -> 이천만원 (\20,000,000원) | H6: =VLOOKUP(B6,[1]계약체결용!$B:$K,7,0) -> 일룸 가구 구미점 | I6: =VLOOKUP(B6,[1]계약체결용!$B:$K,8,0) -> 283-05-01540 | J6: =VLOOKUP(B6,[1]계약체결용!$B:$K,9,0) -> 김관우, 김동윤, 박정애 | K6: =VLOOKUP(B6,[1]계약체결용!$B:$K,10,0) -> 경북 구미시 산업로28길 4 | L6: 283-05-01540 | M6: =VLOOKUP(L6,'[2]25년계약체결용'!$I$2:$O$72,7,0) -> ktongyun@hanmail.net
B7: 김포5 | C7: =VLOOKUP(B7,'[1]2503기준유통망'!$B:$E,4,0) -> B/S-Shop | D7: 현금 | E7: 이천만원 | F7: 20,000,000원 | G7: =E7&" (\"&F7&")" -> 이천만원 (\20,000,000원) | H7: =VLOOKUP(B7,[1]계약체결용!$B:$K,7,0) -> 일룸김포점 | I7: =VLOOKUP(B7,[1]계약체결용!$B:$K,8,0) -> 137-17-39033 | J7: =VLOOKUP(B7,[1]계약체결용!$B:$K,9,0) -> 장 미 영 | K7: =VLOOKUP(B7,[1]계약체결용!$B:$K,10,0) -> 경기 김포시 풍무동 27-4 1,2층 | L7: 137-17-39033 | M7: =VLOOKUP(L7,'[2]25년계약체결용'!$I$2:$O$72,7,0) -> kanges232@naver.com
B8: 김해2 | C8: =VLOOKUP(B8,'[1]2503기준유통망'!$B:$E,4,0) -> B/S-Shop | D8: 현금 | E8: 이천만원 | F8: 20,000,000원 | G8: =E8&" (\"&F8&")" -> 이천만원 (\20,000,000원) | H8: =VLOOKUP(B8,[1]계약체결용!$B:$K,7,0) -> 일룸 김해브랜드샵 | I8: =VLOOKUP(B8,[1]계약체결용!$B:$K,8,0) -> 615-17-27736 | J8: =VLOOKUP(B8,[1]계약체결용!$B:$K,9,0) -> 박 효 정 | K8: =VLOOKUP(B8,[1]계약체결용!$B:$K,10,0) -> 경남 김해시 풍유동 47-3 | L8: 615-17-27736 | M8: =VLOOKUP(L8,'[2]25년계약체결용'!$I$2:$O$72,7,0) -> iloomju@naver.com
B9: 달서5 | C9: =VLOOKUP(B9,'[1]2503기준유통망'!$B:$E,4,0) -> B/S-Shop | D9: 현금 | E9: 이천만원 | F9: 20,000,000원 | G9: =E9&" (\"&F9&")" -> 이천만원 (\20,000,000원) | H9: =VLOOKUP(B9,[1]계약체결용!$B:$K,7,0) -> 일룸달서프리미엄샵 | I9: =VLOOKUP(B9,[1]계약체결용!$B:$K,8,0) -> 514-19-58959 | J9: =VLOOKUP(B9,[1]계약체결용!$B:$K,9,0) -> 서 미 경 | K9: =VLOOKUP(B9,[1]계약체결용!$B:$K,10,0) -> 대구 달서구 조암로 200(유천동) | L9: 514-19-58959 | M9: heraseo219@nate.com
B10: 덕진2 | C10: =VLOOKUP(B10,'[1]2503기준유통망'!$B:$E,4,0) -> B/S-Shop | D10: 현금 | E10: 이천만원 | F10: 20,000,000원 | G10: =E10&" (\"&F10&")" -> 이천만원 (\20,000,000원) | H10: =VLOOKUP(B10,[1]계약체결용!$B:$K,7,0) -> 일룸 덕진점 | I10: =VLOOKUP(B10,[1]계약체결용!$B:$K,8,0) -> 418-06-94448 | J10: =VLOOKUP(B10,[1]계약체결용!$B:$K,9,0) -> 유 수 정 | K10: =VLOOKUP(B10,[1]계약체결용!$B:$K,10,0) -> 전북 전주시 덕진구 송천중앙로 6 | L10: 418-06-94448 | M10: elioom@nate.com
B11: 마산6 | C11: =VLOOKUP(B11,'[1]2503기준유통망'!$B:$E,4,0) -> B/S-Shop | D11: 현금 | E11: 이천만원 | F11: 20,000,000원 | G11: =E11&" (\"&F11&")" -> 이천만원 (\20,000,000원) | H11: =VLOOKUP(B11,[1]계약체결용!$B:$K,7,0) -> 퍼시스스마트OPC(극동) | I11: =VLOOKUP(B11,[1]계약체결용!$B:$K,8,0) -> 608-47-60393 | J11: =VLOOKUP(B11,[1]계약체결용!$B:$K,9,0) -> 강 호 근 | K11: =VLOOKUP(B11,[1]계약체결용!$B:$K,10,0) -> 경남 창원시 마산회원구 봉양로 187(봉암동) | L11: 608-47-60393 | M11: smartopc@naver.com
B12: 봉선5 | C12: =VLOOKUP(B12,'[1]2503기준유통망'!$B:$E,4,0) -> B/S-Shop | D12: 현금 | E12: 이천만원 | F12: 20,000,000원 | G12: =E12&" (\"&F12&")" -> 이천만원 (\20,000,000원) | H12: =VLOOKUP(B12,[1]계약체결용!$B:$K,7,0) -> 주식회사 일룸앤데스커 | I12: =VLOOKUP(B12,[1]계약체결용!$B:$K,8,0) -> 408-88-02821 | J12: =VLOOKUP(B12,[1]계약체결용!$B:$K,9,0) -> 조 평 호 | K12: =VLOOKUP(B12,[1]계약체결용!$B:$K,10,0) -> 광주광역시 남구 봉선로 16 (주월동) 1층 | L12: 408-88-02821 | M12: kimh2488@naver.com
B13: 부천3 | C13: =VLOOKUP(B13,'[1]2503기준유통망'!$B:$E,4,0) -> B/S-Shop | D13: 현금 | E13: 이천만원 | F13: 20,000,000원 | G13: =E13&" (\"&F13&")" -> 이천만원 (\20,000,000원) | H13: =VLOOKUP(B13,[1]계약체결용!$B:$K,7,0) -> 일룸 부천점 | I13: =VLOOKUP(B13,[1]계약체결용!$B:$K,8,0) -> 313-36-00088 | J13: =VLOOKUP(B13,[1]계약체결용!$B:$K,9,0) -> 최 민 영 | K13: =VLOOKUP(B13,[1]계약체결용!$B:$K,10,0) -> 경기 부천시 길주로 462 | L13: 313-36-00088 | M13: =VLOOKUP(L13,'[2]25년계약체결용'!$I$2:$O$72,7,0) -> iloombc@naver.com
B14: 분당2 | C14: =VLOOKUP(B14,'[1]2503기준유통망'!$B:$E,4,0) -> B/S-Shop | D14: 현금 | E14: 이천만원 | F14: 20,000,000원 | G14: =E14&" (\"&F14&")" -> 이천만원 (\20,000,000원) | H14: =VLOOKUP(B14,[1]계약체결용!$B:$K,7,0) -> 일룸분당점 | I14: =VLOOKUP(B14,[1]계약체결용!$B:$K,8,0) -> 135-10-97912 | J14: =VLOOKUP(B14,[1]계약체결용!$B:$K,9,0) -> 최 상 헌 | K14: =VLOOKUP(B14,[1]계약체결용!$B:$K,10,0) -> 경기도 성남시 분당구 대왕판교로214 | L14: 135-10-97912 | M14: =VLOOKUP(L14,'[2]25년계약체결용'!$I$2:$O$72,7,0) -> csh6797@naver.com
B15: 빛고을3 | C15: B/S-Shop | D15: 현금 | E15: 이천만원 | F15: 20,000,000원 | G15: =E15&" (\"&F15&")" -> 이천만원 (\20,000,000원) | H15: 일룸빛고을점 | I15: 451-48-01330 | J15: 최 정 우 | K15: 광주 광산구 하남대로 352 3층 일룸빛고을점 | L15: 451-48-01330 | M15: woowby@naver.com
B16: 서대전3 | C16: =VLOOKUP(B16,'[1]2503기준유통망'!$B:$E,4,0) -> B/S-Shop | D16: 현금 | E16: 이천만원 | F16: 20,000,000원 | G16: =E16&" (\"&F16&")" -> 이천만원 (\20,000,000원) | H16: =VLOOKUP(B16,[1]계약체결용!$B:$K,7,0) -> 일룸서대전점2 | I16: =VLOOKUP(B16,[1]계약체결용!$B:$K,8,0) -> 305-29-60452 | J16: =VLOOKUP(B16,[1]계약체결용!$B:$K,9,0) -> 김 영 애 | K16: =VLOOKUP(B16,[1]계약체결용!$B:$K,10,0) -> 대전 중구 중앙로 8 (문화동, 가구갤러리 8층) | L16: 305-29-60452 | M16: =VLOOKUP(L16,'[2]25년계약체결용'!$I$2:$O$72,7,0) -> iloom7052@hanmail.net
B17: 서산4 | C17: B/S-Shop | D17: 현금 | E17: 이천만원 | F17: 20,000,000원 | G17: =E17&" (\"&F17&")" -> 이천만원 (\20,000,000원) | H17: 일룸 서산점 | I17: 123-47-01118 | J17: 김정남 | K17: 충청남도 서산시 서해로 3449(석림동) | L17: 123-47-01118 | M17: kjn0120@naver.com
B18: 세종2 | C18: =VLOOKUP(B18,'[1]2503기준유통망'!$B:$E,4,0) -> B/S-Shop | D18: 현금 | E18: 이천만원 | F18: 20,000,000원 | G18: =E18&" (\"&F18&")" -> 이천만원 (\20,000,000원) | H18: =VLOOKUP(B18,[1]계약체결용!$B:$K,7,0) -> 일룸 세종점 | I18: =VLOOKUP(B18,[1]계약체결용!$B:$K,8,0) -> 760-33-00129 | J18: =VLOOKUP(B18,[1]계약체결용!$B:$K,9,0) -> 박정나, 이상연 | K18: =VLOOKUP(B18,[1]계약체결용!$B:$K,10,0) -> 세종 아름동 1313 정원타워 3,4층 | L18: 760-33-00129 | M18: daikii@naver.com
B19: 수성5 | C19: =VLOOKUP(B19,'[1]2503기준유통망'!$B:$E,4,0) -> B/S-Shop | D19: 현금 | E19: 이천만원 | F19: 20,000,000원 | G19: =E19&" (\"&F19&")" -> 이천만원 (\20,000,000원) | H19: =VLOOKUP(B19,[1]계약체결용!$B:$K,7,0) -> 일룸수성점 | I19: =VLOOKUP(B19,[1]계약체결용!$B:$K,8,0) -> 502-21-75604 | J19: =VLOOKUP(B19,[1]계약체결용!$B:$K,9,0) -> 조진희, 차인호 | K19: =VLOOKUP(B19,[1]계약체결용!$B:$K,10,0) -> 대구 수성구 희망로 152 | L19: 502-21-75604 | M19: wlsl4258@hanmail.net
B20: 순천4 | C20: =VLOOKUP(B20,'[1]2503기준유통망'!$B:$E,4,0) -> B/S-Shop | D20: 현금 | E20: 이천만원 | F20: 20,000,000원 | G20: =E20&" (\"&F20&")" -> 이천만원 (\20,000,000원) | H20: =VLOOKUP(B20,[1]계약체결용!$B:$K,7,0) -> 주식회사 일룸 | I20: =VLOOKUP(B20,[1]계약체결용!$B:$K,8,0) -> 142-88-00388 | J20: =VLOOKUP(B20,[1]계약체결용!$B:$K,9,0) -> 김 대 현 | K20: =VLOOKUP(B20,[1]계약체결용!$B:$K,10,0) -> 전남 순천시 중앙로 118 | L20: 142-88-00388 | M20: popeyes2@hanmail.net
B21: 안동5 | C21: =VLOOKUP(B21,'[1]2503기준유통망'!$B:$E,4,0) -> B/S-Shop | D21: 현금 | E21: 이천만원 | F21: 20,000,000원 | G21: =E21&" (\"&F21&")" -> 이천만원 (\20,000,000원) | H21: =VLOOKUP(B21,[1]계약체결용!$B:$K,7,0) -> 일룸안동점 | I21: =VLOOKUP(B21,[1]계약체결용!$B:$K,8,0) -> 511-08-44988 | J21: =VLOOKUP(B21,[1]계약체결용!$B:$K,9,0) -> 조현주, 박주홍 | K21: =VLOOKUP(B21,[1]계약체결용!$B:$K,10,0) -> 경북 안동시 하이마로 151 | L21: 511-08-44988 | M21: =VLOOKUP(L21,'[2]25년계약체결용'!$I$2:$O$72,7,0) -> amaxs@hanmail.net
B22: 안산상록수2 | C22: =VLOOKUP(B22,'[1]2503기준유통망'!$B:$E,4,0) -> B/S-Shop | D22: 현금 | E22: 이천만원 | F22: 20,000,000원 | G22: =E22&" (\"&F22&")" -> 이천만원 (\20,000,000원) | H22: =VLOOKUP(B22,[1]계약체결용!$B:$K,7,0) -> 일룸안산상록수점 | I22: =VLOOKUP(B22,[1]계약체결용!$B:$K,8,0) -> 207-04-55609 | J22: 노수민 | K22: =VLOOKUP(B22,[1]계약체결용!$B:$K,10,0) -> 경기 안산시 상록구 용신로 451-1(본오동,1,2층) | L22: 207-04-55609 | M22: =VLOOKUP(L22,'[2]25년계약체결용'!$I$2:$O$72,7,0) -> wish2199@naver.com
B23: 양산3 | C23: =VLOOKUP(B23,'[1]2503기준유통망'!$B:$E,4,0) -> B/S-Shop | D23: 현금 | E23: 이천만원 | F23: 20,000,000원 | G23: =E23&" (\"&F23&")" -> 이천만원 (\20,000,000원) | H23: =VLOOKUP(B23,[1]계약체결용!$B:$K,7,0) -> 일룸양산점 | I23: =VLOOKUP(B23,[1]계약체결용!$B:$K,8,0) -> 463-03-00712 | J23: =VLOOKUP(B23,[1]계약체결용!$B:$K,9,0) -> 남 명 현 | K23: =VLOOKUP(B23,[1]계약체결용!$B:$K,10,0) -> 경남 양산시 물금읍 황산로 497 | L23: 463-03-00712 | M23: =VLOOKUP(L23,'[2]25년계약체결용'!$I$2:$O$72,7,0) -> godid56@nate.com
B24: 연제4 | C24: =VLOOKUP(B24,'[1]2503기준유통망'!$B:$E,4,0) -> B/S-Shop | D24: 현금 | E24: 이천만원 | F24: 20,000,000원 | G24: =E24&" (\"&F24&")" -> 이천만원 (\20,000,000원) | H24: =VLOOKUP(B24,[1]계약체결용!$B:$K,7,0) -> (주)일룸연제점 | I24: =VLOOKUP(B24,[1]계약체결용!$B:$K,8,0) -> 388-87-01424 | J24: =VLOOKUP(B24,[1]계약체결용!$B:$K,9,0) -> 이 철 희 | K24: =VLOOKUP(B24,[1]계약체결용!$B:$K,10,0) -> 부산 연제구 거제대로 297, 2~3층 | L24: 388-87-01424 | M24: auk0903@naver.com
B25: 원주3 | C25: =VLOOKUP(B25,'[1]2503기준유통망'!$B:$E,4,0) -> B/S-Shop | D25: 현금 | E25: 이천만원 | F25: 20,000,000원 | G25: =E25&" (\"&F25&")" -> 이천만원 (\20,000,000원) | H25: =VLOOKUP(B25,[1]계약체결용!$B:$K,7,0) -> 일룸원주점 | I25: =VLOOKUP(B25,[1]계약체결용!$B:$K,8,0) -> 224-07-71963 | J25: =VLOOKUP(B25,[1]계약체결용!$B:$K,9,0) -> 이 정 복 | K25: =VLOOKUP(B25,[1]계약체결용!$B:$K,10,0) -> 강원 원주시 호저면 원문로 668-9 만종가구단지 2층 | L25: 224-07-71963 | M25: jungbok35@hanmail.net
B26: 의정부8 | C26: =VLOOKUP(B26,'[1]2503기준유통망'!$B:$E,4,0) -> B/S-Shop | D26: 현금 | E26: 이천만원 | F26: 20,000,000원 | G26: =E26&" (\"&F26&")" -> 이천만원 (\20,000,000원) | H26: =VLOOKUP(B26,[1]계약체결용!$B:$K,7,0) -> 일룸의정부브랜드샵 | I26: =VLOOKUP(B26,[1]계약체결용!$B:$K,8,0) -> 550-88-00221 | J26: =VLOOKUP(B26,[1]계약체결용!$B:$K,9,0) -> 이 경 숙 | K26: =VLOOKUP(B26,[1]계약체결용!$B:$K,10,0) -> 경기 의정부시 민락로 397 | L26: 550-88-00221 | M26: =VLOOKUP(L26,'[2]25년계약체결용'!$I$2:$O$72,7,0) -> jail5775@hanmail.net
B27: 인천중앙2 | C27: =VLOOKUP(B27,'[1]2503기준유통망'!$B:$E,4,0) -> B/S-Shop | D27: 현금 | E27: 이천만원 | F27: 20,000,000원 | G27: =E27&" (\"&F27&")" -> 이천만원 (\20,000,000원) | H27: =VLOOKUP(B27,[1]계약체결용!$B:$K,7,0) -> (주)알루컴 인천점 | I27: =VLOOKUP(B27,[1]계약체결용!$B:$K,8,0) -> 105-85-41701 | J27: =VLOOKUP(B27,[1]계약체결용!$B:$K,9,0) -> 이 종 균 | K27: =VLOOKUP(B27,[1]계약체결용!$B:$K,10,0) -> 인천 남동구 인주대로 644 | L27: 105-85-41701 | M27: lhs0301@kakao.com
B28: 일산킨텍스 | C28: =VLOOKUP(B28,'[1]2503기준유통망'!$B:$E,4,0) -> B/S-Shop | D28: 현금 | E28: 이천만원 | F28: 20,000,000원 | G28: =E28&" (\"&F28&")" -> 이천만원 (\20,000,000원) | H28: =VLOOKUP(B28,[1]계약체결용!$B:$K,7,0) -> (주)플랜 디 | I28: =VLOOKUP(B28,[1]계약체결용!$B:$K,8,0) -> 670-81-01506 | J28: =VLOOKUP(B28,[1]계약체결용!$B:$K,9,0) -> 김정은, 안중협 | K28: 경기도 고양시 일산동구 장항동 1825 | L28: 670-81-01506 | M28: =VLOOKUP(L28,'[2]25년계약체결용'!$I$2:$O$72,7,0) -> garnet212@naver.com
B29: 전군2 | C29: =VLOOKUP(B29,'[1]2503기준유통망'!$B:$E,4,0) -> B/S-Shop | D29: 현금 | E29: 이천만원 | F29: 20,000,000원 | G29: =E29&" (\"&F29&")" -> 이천만원 (\20,000,000원) | H29: =VLOOKUP(B29,[1]계약체결용!$B:$K,7,0) -> 일룸전군점 | I29: =VLOOKUP(B29,[1]계약체결용!$B:$K,8,0) -> 403-03-30193 | J29: =VLOOKUP(B29,[1]계약체결용!$B:$K,9,0) -> 안 상 준 | K29: =VLOOKUP(B29,[1]계약체결용!$B:$K,10,0) -> 전북 김제시 백구면 영상3길 28-26 | L29: 403-03-30193 | M29: =VLOOKUP(L29,'[2]25년계약체결용'!$I$2:$O$72,7,0) -> iloom4200@naver.com
B30: 중화산4 | C30: =VLOOKUP(B30,'[1]2503기준유통망'!$B:$E,4,0) -> B/S-Shop | D30: 현금 | E30: 이천만원 | F30: 20,000,000원 | G30: =E30&" (\"&F30&")" -> 이천만원 (\20,000,000원) | H30: =VLOOKUP(B30,[1]계약체결용!$B:$K,7,0) -> 일룸중화산점 | I30: =VLOOKUP(B30,[1]계약체결용!$B:$K,8,0) -> 402-20-78721 | J30: =VLOOKUP(B30,[1]계약체결용!$B:$K,9,0) -> 양 유 진 | K30: =VLOOKUP(B30,[1]계약체결용!$B:$K,10,0) -> 전북 전주시 완산구 중화산동2가 528-6 | L30: 402-20-78721 | M30: =VLOOKUP(L30,'[2]25년계약체결용'!$I$2:$O$72,7,0) -> power5550@hanmail.net
B31: 진주2 | C31: =VLOOKUP(B31,'[1]2503기준유통망'!$B:$E,4,0) -> B/S-Shop | D31: 현금 | E31: 이천만원 | F31: 20,000,000원 | G31: =E31&" (\"&F31&")" -> 이천만원 (\20,000,000원) | H31: =VLOOKUP(B31,[1]계약체결용!$B:$K,7,0) -> 일룸진주점 | I31: =VLOOKUP(B31,[1]계약체결용!$B:$K,8,0) -> 613-06-76176 | J31: =VLOOKUP(B31,[1]계약체결용!$B:$K,9,0) -> 김지융, 김현실 | K31: =VLOOKUP(B31,[1]계약체결용!$B:$K,10,0) -> 경남 진주시 진주대로 638(가좌동) | L31: 613-06-76176 | M31: =VLOOKUP(L31,'[2]25년계약체결용'!$I$2:$O$72,7,0) -> rlduql_par@naver.com
B32: 창원3 | C32: =VLOOKUP(B32,'[1]2503기준유통망'!$B:$E,4,0) -> B/S-Shop | D32: 현금 | E32: 이천만원 | F32: 20,000,000원 | G32: =E32&" (\"&F32&")" -> 이천만원 (\20,000,000원) | H32: =VLOOKUP(B32,[1]계약체결용!$B:$K,7,0) -> (주)창원퍼시스 | I32: =VLOOKUP(B32,[1]계약체결용!$B:$K,8,0) -> 609-81-43386 | J32: =VLOOKUP(B32,[1]계약체결용!$B:$K,9,0) -> 정 진 환 | K32: =VLOOKUP(B32,[1]계약체결용!$B:$K,10,0) -> 경상남도 창원시 의창구 창원대로 360 | L32: 609-81-43386 | M32: su2774@nate.com
B33: 천안불당3 | C33: =VLOOKUP(B33,'[1]2503기준유통망'!$B:$E,4,0) -> B/S-Shop | D33: 현금 | E33: 이천만원 | F33: 20,000,000원 | G33: =E33&" (\"&F33&")" -> 이천만원 (\20,000,000원) | H33: =VLOOKUP(B33,[1]계약체결용!$B:$K,7,0) -> 일룸천안불당점 | I33: =VLOOKUP(B33,[1]계약체결용!$B:$K,8,0) -> 416-22-25834 | J33: 김은미, 주세형 | K33: =VLOOKUP(B33,[1]계약체결용!$B:$K,10,0) -> 충남 천안시 서북구 검은들3길 36 (불당동) | L33: 416-22-25834 | M33: =VLOOKUP(L33,'[2]25년계약체결용'!$I$2:$O$72,7,0) -> skylove2809@hanmail.net
B34: 청남3 | C34: =VLOOKUP(B34,'[1]2503기준유통망'!$B:$E,4,0) -> B/S-Shop | D34: 현금 | E34: 이천만원 | F34: 20,000,000원 | G34: =E34&" (\"&F34&")" -> 이천만원 (\20,000,000원) | H34: =VLOOKUP(B34,[1]계약체결용!$B:$K,7,0) -> 일룸청남점 | I34: =VLOOKUP(B34,[1]계약체결용!$B:$K,8,0) -> 745-10-00252 | J34: =VLOOKUP(B34,[1]계약체결용!$B:$K,9,0) -> 박 종 상 | K34: =VLOOKUP(B34,[1]계약체결용!$B:$K,10,0) -> 충북 청주시 서원구 남이면 가구단지길 21-3 청남가구단지 105호 | L34: 745-10-00252 | M34: =VLOOKUP(L34,'[2]25년계약체결용'!$I$2:$O$72,7,0) -> brqok@naver.com
B35: 청주6 | C35: =VLOOKUP(B35,'[1]2503기준유통망'!$B:$E,4,0) -> B/S-Shop | D35: 현금 | E35: 이천만원 | F35: 20,000,000원 | G35: =E35&" (\"&F35&")" -> 이천만원 (\20,000,000원) | H35: =VLOOKUP(B35,[1]계약체결용!$B:$K,7,0) -> (주)조은파트너스 | I35: =VLOOKUP(B35,[1]계약체결용!$B:$K,8,0) -> 335-87-02787 | J35: =VLOOKUP(B35,[1]계약체결용!$B:$K,9,0) -> 최 현 수 | K35: =VLOOKUP(B35,[1]계약체결용!$B:$K,10,0) -> 충북 청주시 상당구 용암동 1587 | L35: 335-87-02787 | M35: mjhs77@naver.com
B36: 청주중앙4 | C36: =VLOOKUP(B36,'[1]2503기준유통망'!$B:$E,4,0) -> B/S-Shop | D36: 현금 | E36: 이천만원 | F36: 20,000,000원 | G36: =E36&" (\"&F36&")" -> 이천만원 (\20,000,000원) | H36: =VLOOKUP(B36,[1]계약체결용!$B:$K,7,0) -> (주)일룸청주중앙점 | I36: =VLOOKUP(B36,[1]계약체결용!$B:$K,8,0) -> 785-86-00352 | J36: =VLOOKUP(B36,[1]계약체결용!$B:$K,9,0) -> 함 지 연 | K36: =VLOOKUP(B36,[1]계약체결용!$B:$K,10,0) -> 충북 청주시 흥덕구 강서로 55, 2층 | L36: 785-86-00352 | M36: =VLOOKUP(L36,'[2]25년계약체결용'!$I$2:$O$72,7,0) -> iloom1@nate.com
B37: 춘천3 | C37: =VLOOKUP(B37,'[1]2503기준유통망'!$B:$E,4,0) -> B/S-Shop | D37: 현금 | E37: 이천만원 | F37: 20,000,000원 | G37: =E37&" (\"&F37&")" -> 이천만원 (\20,000,000원) | H37: =VLOOKUP(B37,[1]계약체결용!$B:$K,7,0) -> 퍼시스춘천전시장 | I37: =VLOOKUP(B37,[1]계약체결용!$B:$K,8,0) -> 221-02-56686 | J37: =VLOOKUP(B37,[1]계약체결용!$B:$K,9,0) -> 이 신 구 | K37: =VLOOKUP(B37,[1]계약체결용!$B:$K,10,0) -> 강원 춘천시 동면 만천리 700번지 | L37: 221-02-56686 | M37: 2625577@gmail.com
B38: 포항2 | C38: =VLOOKUP(B38,'[1]2503기준유통망'!$B:$E,4,0) -> B/S-Shop | D38: 현금 | E38: 이천만원 | F38: 20,000,000원 | G38: =E38&" (\"&F38&")" -> 이천만원 (\20,000,000원) | H38: =VLOOKUP(B38,[1]계약체결용!$B:$K,7,0) -> 일룸포항점 | I38: =VLOOKUP(B38,[1]계약체결용!$B:$K,8,0) -> 506-04-65571 | J38: =VLOOKUP(B38,[1]계약체결용!$B:$K,9,0) -> 김 미 경 | K38: =VLOOKUP(B38,[1]계약체결용!$B:$K,10,0) -> 경북 포항시 북구 환호로 75 | L38: 506-04-65571 | M38: =VLOOKUP(L38,'[2]25년계약체결용'!$I$2:$O$72,7,0) -> hnhhnhh@hanmail.net
B39: 포항중앙2 | C39: =VLOOKUP(B39,'[1]2503기준유통망'!$B:$E,4,0) -> B/S-Shop | D39: 현금 | E39: 이천만원 | F39: 20,000,000원 | G39: =E39&" (\"&F39&")" -> 이천만원 (\20,000,000원) | H39: =VLOOKUP(B39,[1]계약체결용!$B:$K,7,0) -> 일룸포항중앙점 | I39: =VLOOKUP(B39,[1]계약체결용!$B:$K,8,0) -> 506-14-15162 | J39: =VLOOKUP(B39,[1]계약체결용!$B:$K,9,0) -> 신 현 정 | K39: =VLOOKUP(B39,[1]계약체결용!$B:$K,10,0) -> 경북 포항시 북구 중흥로213번길 49 | L39: 506-14-15162 | M39: =VLOOKUP(L39,'[2]25년계약체결용'!$I$2:$O$72,7,0) -> shjj_2000@hanmail.net
B40: 하단3 | C40: =VLOOKUP(B40,'[1]2503기준유통망'!$B:$E,4,0) -> B/S-Shop | D40: 현금 | E40: 이천만원 | F40: 20,000,000원 | G40: =E40&" (\"&F40&")" -> 이천만원 (\20,000,000원) | H40: =VLOOKUP(B40,[1]계약체결용!$B:$K,7,0) -> 일룸부산하단점 | I40: =VLOOKUP(B40,[1]계약체결용!$B:$K,8,0) -> 617-29-91066 | J40: =VLOOKUP(B40,[1]계약체결용!$B:$K,9,0) -> 우 영 숙 | K40: =VLOOKUP(B40,[1]계약체결용!$B:$K,10,0) -> 부산광역시 사하구 낙동남로 1359 (하단동) | L40: 617-29-91066 | M40: iloom0710@naver.com
B41: 롯데광복2 | C41: =VLOOKUP(B41,'[1]2503기준유통망'!$B:$E,4,0) -> b/s-shop (입점) | D41: 현금 | E41: 이천만원 | F41: 20,000,000원 | G41: =E41&" (\"&F41&")" -> 이천만원 (\20,000,000원) | H41: 일룸 롯데광복점 | I41: 173-62-00679 | J41: 조 정 혁 | K41: 부산광역시 중구 중앙대로 2, 8층 | L41: 173-62-00679 | M41: iloomgo@naver.com
...
