Workbook

Sheet 계약서
L2: 대리점명 | M2: 계약기간 | N2: 매장유형 | O2: 거래보증금
L3: 현대목동 | M3: 2026년 5월 1일 ~ 2027년 3월 31일 | N3: 투자형B-입점 | O3: 이천만원 (₩20,000,000원)
M4: 상호 | N4: 사업자번호 | O4: 대표자 | P4: 주소
M5: 페드라 | N5: 417-10-72598 | O5: 안 중 우 | P5: 경기도 고양시 덕양구 고양대로 1955, B1층(동산동)
A6: 일룸 위탁판매 대리점 계약서 | L6: 계약날짜 | M6: 46143
C15: ◇ 계약기간 : | D15: 2026년 5월 1일 ~ 2027년 3월 31일 | L15: 체크
C18: ◇ 거래보증금 : | D18: 이천만원 (₩20,000,000원) | L18: 체크
M20: ※거래보증금 개별운영 예외로 스타필드 수원(6층)점 거래보증금과 통합 운영
C21: ◇ 매장유형 : | D21: 투자형B-입점 | L21: 체크 | M21: 스수키즈
C24: ◇ 납품방법 및 장소
C25: 납품방법 : 공급업자 직접 운송 및 시공
C26: 납품장소 : 고객 또는 대리점 지정 장소
A33: ㈜일룸 (이하 공급업자)과 페드라(일룸 현대목동) (이하 대리점)은 신의에 따라 | L33: 체크
A34: 성실히 계약상의 권리를 행사하고, 의무를 이행할 것을 확약하며, 그 증거로써 이 계약서를 작성하여 당사자가
A35: 서명 또는 기명날인한 후 각각 1부씩 보관한다.
B44: "공급업자" | C44: 상호 : | D44: 주식회사 일룸 (215-86-93600)
C45: 주소 : | D45: 서울특별시 송파구 오금동 45-1 퍼시스빌딩 8층
C46: 대표 : | D46: 정 보 은 | H46: (인)
B49: "대리점" | C49: 상호 : | D49: 페드라 (일룸 현대목동점 / 417-10-72598) | L49: 체크
C50: 주소 : | D50: 경기도 고양시 덕양구 고양대로 1955, B1층(동산동) | L50: 체크
C51: 대표 : | D51: 안 중 우 | H51: (인) | L51: 체크
B64: 제1조 [목적]
B65: 이 계약은 공급업자와 대리점간의 대리점거래에 있어서 양 당사자 사이의 공정한 계약조건에 따른 기본적인 권리와 의무를
B66: 제시하는 것을 목적으로 한다.
B68: 제2조 [기본원칙]
B69: 1) 공급업자와 대리점은 대등한 지위에서 이 계약상의 의무를 신의에 따라 성실히 이행함으로써 상호 공정한
B70: 거래관계와 동반성장을 추구한다.
B71: 2) 공급업자와 대리점은 이 계약의 체결 및 이행과 관련하여 「독점규제 및 공정거래에 관한 법률」,
B72: 「약관의 규제에 관한 법률」, 「대리점거래의 공정화에 관한 법률」 등의 관계 법령을 준수한다.
B74: 제3조 [공정거래 준수 및 동반성장 지원]
B75: 1) 공급업자와 대리점은 공정하고 투명한 거래를 위하여 다음 각 호의 내용을 준수한다.
B76: ① 상대방에게 금품, 향응, 편의 또는 접대를 요구하거나 제공해서는 아니 되며, 위법하거나 부당한 행위를
B77: 하지 아니한다.
... B151: 3) 제1항의 판매수수료는 매월 1일부터 말일까지 출고분에 대하여 다음달 15일까지 지급함을 원칙으로 한다.
B152: 4) 계약이 종료되는 2027년 3월의 판매수수료는 2027년 4월 15일까지 지급하기로 한다. | L152: 계약종료월 확인
B154: 제10조 [판매수수료의 상계]
B155: 공급업자는 다음 각 호의 경우, 대리점에게 지급할 판매수수료와 대리점에 대한 채권을 상계처리 할 수 있다.
B156: ① 대리점 또는 대리점 직원이 계약상의 의무를 위반하거나 게을리함으로써 공급업자에게 손해가 발생한 경우
B157: ② 대리점에 대한 공급업자의 채권이 발생한 경우
B159: 제11조 [시설과 인력의 확보]
...

Sheet 약정서(수수료-투자b입점)
B3: 위탁판매대리점 판매수수료 및 지원금 약정서
B6: ㈜일룸 (이하 공급업자)과 페드라 (일룸 현대목동) (이하 대리점) 간에 | N6: 체크
B7: 다음과 같이 판매수수료 및 지원금 약정을 체결한다.
B11: 제1조 [목적]
B12: 본 약정은 공급업자가 임차료 및 쇼핑몰의 입점수수료를 부담하는 매장과 관련하여 공급자와 대리점 간의 상호 간 이익을 도모하기 위해
B13: 일룸 위탁판매대리점 계약서 (이하 "본 계약”이라 함)에 따른 계약조건(제4조, 제5조, 제6조, 제7조, 제9조등)을 추가 및 보완함으로써
B14: 상호 간의 신의에 따라 계약을 성실히 이행할 수 있도록 그 내용을 구체적으로 정하는 것을 목적으로 한다.
B16: 제2조 [공급품목]
B17: 1) 공급업자가 고객에게 판매하는 상품의 유형은 다음과 같다.
B18: 제품유형 | D18: 제품 특성 등 | J18: 비고
B19: A 유형 | D19: - 오프라인 매장, 온라인 공식몰을 주 판매채널로 활용 - 상대적으로 구매에 있어서 가격민감도가 낮은 제품 - 제품의 가치에 따른 적정 가격 전략 | J19: 주요채널 지향 제품
B20: B 유형 | D20: - 온라인 외부몰, 입주시장, 특화매장 등 다양한 경로의 판매채널을 목표 - 상대적으로 구매에 있어서의 가격민감도가 높은 제품 - 고객접점 확보와 대량 판매를 목적으로 하는 가격 전략 | J20: 다채널 지향 제품
B22: 2) 공급업자는 전항의 상품 유형별 세부 품목 내역 및 소비자가격을 대리점이 확인할 수 있도록 공급업자의
B23: 전산주문시스템 (https://www.connectplus.co.kr/pos/index.html / 이하 “커넥트플러스")에 사전에 공지한다.
B25: 제3조 [판매수수료]
B26: 1) 판매수수료는 아래와 같이 누진제 수수료율을 적용하기로 한다.
C27: (단위 : 원, VAT별도)
C28: 구분 | D28: 매출구간
D29: 150,000,000 이하 | F29: 150,000,000 초과 ~ 200,000,000 이하 | H29: 200,000,000 초과 ~ 300,000,000 이하 | J29: 300,000,000 초과
C30: 판매수수료율 | D30: 0.11 | F30: 0.08 | H30: 0.06 | J30: 0.05
C31: * 본 수수료율의 매출액은 위탁가격을 기준으로하며, 대리점 소유의 전시품 판매를 제외한 POS결제금액 기준
C32: * 예시: 대리점 소유의 전시품 판매를 제외한 POS매출액 270,000,000원인 경우 판매수수료
C33: 150,000,000 * 11% + 50,000,000 * 8% + 70,000,000 * 7% = 25,400,000(원)
B34: 2) 공급업자와 대리점은 판촉행사 등 필요한 경우 별도 서면 합의에 따라 별도의 판매수수료를 정할 수 있다. | N34: 150000000 | O34: 0.11 | P34: =N34*O34 -> 16500000
N35: 50000000 | O35: 0.08 | P35: =N35*O35 -> 4000000
B36: 제4조 [판매수수료 지급] | N36: 70000000 | O36: 0.07 | P36: =N36*O36 -> 4900000
B37: 1) 공급업자는 매월 1일부터 말일까지의 위탁판매금액을 기준으로 약정된 판매수수료를 대리점에게 익월 15일까지 지급하며, | P37: =SUM(P34:P36) -> 25400000
B38: 백원 단위 이하는 절사한다.
B39: 2) 공급업자는 대리점에게 지급할 수수료를 공급업자에 대한 대리점의 채무와 상계할 수 있다. | N39: 26년 수정
B40: 다만, 추가 배송비, 추가 시공비, 사다리차 비용, 재배송비 기타 대리점의 주문접수, 정보전달 또는 현장확인 과정에서 발생한 비용은
B41: 대리점의 귀책사유가 있는 경우에 한하여 상계할 수 있다. 이 경우 공급업자는 상계 전에 해당 비용의 발생원인, 상계예정 금액 및 산정근거를
B42: 대리점에게 서면으로 통지하여야 하며, 대리점이 통지를 받은 날부터 [7]일 이내에 이의를 제기한 경우에는 당사자 협의를 거쳐 확정된 범위에서
B43: 상계할 수 있다. 대리점이 위 기간 내 이의를 제기하지 아니한 경우에는 공급업자는 해당 금액을 수수료에서 상계할 수 있다.
B45: 제5조 [수수료 산정 기준 및 매출의 정의] | N45: 26년 추가
B46: 1) 수수료 지급 대상 매출(이하 “수수료 대상 매출”)이라 함은 입점몰에서 POS를 통해 고객과의 직접적인 거래로 발생한 실제 판매금액을 의미한다.
B47: 2) 다음 각 호에 해당하는 금액은 고객과의 거래로 발생한 매출로 보지 아니하며, 수수료 대상 매출에서 제외한다.
B48: ① 매장 운영 등과 관련하여 계약 또는 당사자 간 합의에 따라 대리점이 부담하여야 하는 제반 비용
B49: ② 전시품의 이동, 설치, 철거 등 대리점 소유 자산의 운영 과정에서 발생하는 비용
B50: ③ 기타 그 성질상 고객과의 직접적인 판매거래로 보기 어렵고, 계약 또는 당사자 간 합의에 따라 대리점이 부담하기로 한 비용
B51: 3) 제2항에 따른 비용은 원칙적으로 POS가 아닌 별도의 거래 방식(서브코드 또는 이에 준하는 정산 방식)을 통해 처리하여야 한다.
...

Sheet 약정서(CI,SI)
A3: CI 및 SI 약정서
A6: ㈜일룸 (이하 공급업자)과 페드라 (일룸 현대목동) (이하 대리점) 간에 | K6: 체크
A7: 다음과 같이 CI 및 SI 약정을 체결한다.
B10: - 다 음 -
B13: 제1조 [목적]
B14: 1) 이 약정은 공급업자가 규정하는 브랜드 CI 및 SI를 대리점이 성실하게 준수하고, 공급업자가 대리점에 지원하는 사항 등을 정함을
B15: 목적으로 한다.
B17: 제2조 [용어의 정의]
B18: 1) CI (Corporation identity) : 기업의 심벌마크, 로고타입, 심벌색상 등을 일치시켜 이상적인 브랜드 이미지를 부각함으로써
B19: 새로운 브랜드 이념 확립과 사업영역 확대 등을 꾀하는 경영전략
B20: 2) SI (Shop Identity) : 브랜드의 매장 이미지 통일화 작업으로 매장마다 간판이나 내부 장식, 진열방법, 조명 등을 통일 또는
B21: 규격화 함으로써 소비자의 구매욕구를 불러 일으키는 경영전략
B22: 3) 전시품이란 매장에 전시를 목적으로 전시되는 상품을 의미한다.
B24: 제3조 [매장유형의 구분]
B25: 1) 공급업자는 전시 전문화의 목적을 가지고 대리점의 유형을 아래의 기준에 따라 구분하며, 유형에 맞춰 판매물품 및 지원금,
... B28: ② 본사투자형 매장 (이하 투자형 B-shop) : 인테리어, 매장임대 등 본사 투자형 매장
B29: 2) 공급업자는 신제품 출시, 브랜드 운영정책 변경, 매장 규모 또는 입지 특성 등 합리적인 사유가 있는 경우에 한하여 | K29: 26년 수정
B30: 제1항의 기준을 예외적으로 적용할 수 있다. 이 경우 공급업자는 그 사유와 적용 내용을 사전에 서면으로 안내하여야 하며,
B31: 대리점과 성실히 협의하여야 한다
B33: 제4조 [판매품목의 조정]
B34: 1) 대리점이 제3조의 제반 기준에 따른 매장유형의 필요 조건을 갖추었다 하더라도 공급업자가 공지하였거나 사전에 협의한
B35: CI 및 SI 규정과 전시품 레이아웃 시안을 준수하지 않아 현저하게 브랜드 이미지를 훼손할 경우, 공급업자는 시정을 요청할 수 있으며,
B36: 대리점이 이에 응하지 않는 경우 대리점의 판매 및 전시품목을 제한할 수 있다
B37: 2) 공급업자는 상기 1항 이외에 영업정책 상 필요할 경우 대리점의 판매품목을 예외적으로 조정할 수 있다.
B39: 제5조 [온라인 활동]
B40: 1) 대리점이 온라인상에서 공급업자의 로고, 제품이미지 등을 사용하는 경우 반드시 공급업자의 승인을 받아야 하며, 로고의 임의 변경
B41: 및 무단 복제로 인해 공급업자가 피해를 입지 않도록 대리점은 성실히 협조하여야 한다.
B42: 2) 대리점이 온라인상의 별도 사이트 운영과 블로그, 카페를 포함한 커뮤니티 운영하는 것에 대해 공급업자는 대리점에게
B43: 온라인 활동지침을 제시할 수 있다.
B44: 3) 대리점은 공급업자가 제공하는 매뉴얼과 시안으로 브랜드 이미지에 맞게 사이트와 커뮤니티를 운영하여야 한다. | K44: 26년 수정
B45: 대리점은 공급업자의 상표, 상호, 디자인, 저작물 기타 브랜드 자산을 사용하는 경우, 공급업자가 사전에 제공한 매뉴얼 및
B46: 가이드에 따라 소비자 혼동 방지와 브랜드 동일성 유지를 위한 범위 내에서 이를 사용한다
B47: 4) 대리점의 온라인 활동과 관련한 세부 운영기준은 상표권 보호, 허위·과장표시 방지, 소비자 보호 및 브랜드 자산 관리에 | K47: 26년 수정
B48: 필요한 범위 내에서만 적용한다. 공급업자는 온라인 활동에 관하여 시정을 요청할 경우 그 사유와 범위를 구체적으로 서면 통지하여야
B49: 하며, 대리점은 합리적인 범위 내에서 이에 협조한다.
B51: 제6조 [매장 시설 및 전시]
B52: 1) 대리점이 매장을 개설, 이전하거나 기존 전시를 변경하고자 할 경우에는 매장의 시설 및 전시 계획에 관하여 공급업자가 지정한
B53: 다음과 같은 SI 기준에 준하여 시행한다.
B54: ① 인테리어 및 소품은 공급업자가 추천한 업체 또는 대리점이 직접 진행할 수 있으며, 대리점이 비용 부담한다.
B55: 2) 공급업자는 신제품 출시 혹은 전시환경 개선 등으로 매장 전시 변경을 제의할 수 있고, 대리점은 공급업자와 성실히 협의하여
...

Sheet 약정서(개인정보)
K2: 법무의견서
B3: 개인정보처리 위탁 약정서 | K3: https://ep.fursys.com/WebFlow/view.do?flowNo=eZYVZRVMHFi3XWVIQMM-vLkQrhQ2A-9N04z4NA3_6UA
A6: ㈜일룸 (이하 "위탁자"라 한다)과 페드라 (일룸 현대목동) (이하 "수탁자"라 한다) 는 | K6: 체크
A7: 위탁자의 개인정보 처리 업무를 수탁자에게 위탁함에 있어
A8: 다음과 같은 내용으로 본 업무위탁계약을 체결한다.
B11: - 다 음 -
B14: 제1조 [목적]
B15: 1) 이 계약은 '위탁자'가 개인정보처리업무를 '수탁자'에게 위탁하고, '수탁자'는 이를 승낙하여 '수탁자'의 책임 아래
B16: 성실하게 업무를 완성하도록 하는데 필요한 사항을 정함을 목적으로 한다.
B18: 제2조 [용어의 정의]
B19: 1) 본 계약에서 별도로 정의되지 아니한 용어는「개인정보 보호법」, 같은 법 시행령 및 시행규칙,
B20: 「개인정보의 안전성 확보조치 기준」(행정안전부 고시 제2019-47호) 및「표준 개인정보 보호지침」
B21: (행정안전부 고시 제2017-1호)에서 정의된 바에 따른다.
B23: 제3조 [위탁업무의 목적 및 범위]
B24: 1) '수탁자'는 계약이 정하는 바에 따라 일룸의 위탁운영업체로서 고객서비스 목적으로 다음과 같은 개인정보 처리 업무를 수행한다.
B25: ① 위탁자가 공급하는 일체의 상품 판매를 위한 견적서/주문서 발행 시 개인정보 처리 업무
B26: ② 상품판매와 관련된 A/S 접수, 조치 및 확인 업무
... B30: 제4조 [위탁업무 기간]
B31: 1) 이 계약서에 의한 개인정보 처리업무의 기간은 다음과 같다. (2026년 5월 1일 ~ 2027년 3월 31일) | K31: 체크
B33: 제5조 [재위탁 제한]
B34: 1) '수탁자'는 '위탁자'의 사전 승낙을 얻은 경우를 제외하고 '위탁자'와의 계약상의 권리와 의무의 전부 또는 일부를
B35: 제3자에게 양도하거나 재위탁할 수 없다.
B36: 2) '수탁자'가 다른 제3의 회사와 수탁계약을 할 경우에는 '수탁자'는 해당 사실을 계약 체결 7일 이전에
B37: '위탁자'에게 통보하고 협의하여야 한다.
B39: 제6조 [개인정보의 안전성 확보조치]
B40: 1) '수탁자'는「개인정보 보호법」제23조제2항 및 제24조제3항 및 제29조, 같은 법 시행령 제21조 및 제30조,
B41: 「개인정보의 안전성 확보조치 기준」(행정안전부 고시 제2019-47호)에 따라 개인정보의 안전성 확보에 필요한
B42: 관리적․기술적 조치를 취하여야 한다.
B44: 제7조 [개인정보의 처리제한]
B45: 1) '수탁자'는 계약기간은 물론 계약 종료 후에도 위탁업무 수행 목적 범위를 넘어 개인정보를 이용하거나
B46: 이를 제3자에게 제공 또는 누설하여서는 안 된다.
... B78: '위탁자'는 이를 '수탁자'에게 구상할 수 있다.
C82: 46143
B85: "위탁자" | C85: 상호 : | D85: 주식회사 일룸 (215-86-93600)
C86: 주소 : | D86: 서울특별시 송파구 오금동 45-1 퍼시스빌딩 8층
C87: 대표 : | D87: 정 보 은 | H87: (인)
B90: "수탁자" | C90: 상호 : | D90: 페드라 (일룸 현대목동점 / 417-10-72598)
C91: 주소 : | D91: 경기도 고양시 덕양구 고양대로 1955, B1층(동산동) | K91: 체크
C92: 대표 : | D92: 안 중 우 | H92: (인) | K92: 체크
K93: 체크

Sheet 3D홈플래너 사용권계약서
B3: 3D 홈 플래너 사용권 계약서
B6: ="(주)일룸(이하 '갑'이라 함)과 "&#REF!&" (일룸 "&#REF!&") (이하 '을'이라 함)은" -> #REF! | L6: 체크
B7: 갑이 주식회사 아키드로우(이하 '아키드로우'라 함)로부터 사용권을 획득한
B8: 인테리어 3D 소프트웨어 서비스(이하 "3D 홈 플래너"라 함)의 사용권한을 을에게 부여함에 있어
B9: 다음과 같이 계약을 체결한다.
B11: - 다 음 -
B14: 제1조 [목적]
B15: 본 계약은 갑이 아키드로우로부터 부여받은 3D 홈 플래너 사용권한을 을에게 부여하고, 을이 그에 대한 사용료를 지급함에 있어 당사자간의
B16: 권리와 의무를 규정하는 것을 그 목적으로 한다.
B18: 제2조 [권리의 표시]
B19: 갑은 3D 홈 플래너의 사용과 관련한 권리를 을에게 부여한다.
B21: 제3조 [계약기간 및 범위]
B22: ="1) 본 계약에 따라 을에게 부여되는 권리는 "&#REF!&"까지 존속한다." -> #REF! | L22: 체크
B23: 2) 계약 기간 종료일 30일전까지 갑 또는 을이 상대방에게 계약을 더 이상 연장하지 않겠다는 제시를 하지 않는 경우, 1년 단위로
B24: 자동 연장한다.
B26: 제4조 [을의 의무]
B27: 을은 본 계약상 권리를 이용함에 있어 갑의 명예와 이미지를 손상시키는 행위를 하여서는 아니되고, 관계법령 및 사회상규를 준수하여야 하며,
B28: 제3자의 권리를 침해하지 아니할 것을 보증한다.
B30: 제5조 [사용료의 정산]
B31: 1) 갑은 매월 1일 전까지 아래 내용에 따라 로열티를 산정하여, 을에게 로열티의 지급을 요청한다. | L31: 단가인상 체크
B32: * 로열티 금액 : 3D 홈 플래너 소프트웨어 계정 1개당 65,000원 (VAT별도) | M32: ※영업지원정책 50% 지원
B33: (소프트웨어 계정은 1인당 1계정을 사용하여야 한다.) | L33: 1인1계정 --- 본사와 아키의 계약 상 1인 1서브계정 사용 조항에 따른 문구 추가
B34: =" * 26년 영업지원제도에 의거, "&#REF!&" 사용분에 대해 50% 본사지원" -> #REF! | L34: 체크
B35: 지원 후 금액 : 계정당 월 사용료 32,500원(VAT별도)
B36: 2) 본 조의 내용에도 불구하고 을의 자금 사정 등으로 인해 기한 내에 본 로열티를 지급할 수 없는 경우에는 30일을 초과하지 않는 범위 내에서
B37: 쌍방이 합의하여 지급일을 조정할 수 있다. 이 경우 을은 지연된 기간에 대한 이자는 부담하지 않는다.
B38: 3) 갑이 을에 대해 채무를 부담하는 경우 을은 본 조의 로열티 금액에서 해당 채무를 공제한 후 잔액을 지급할 수 있다.
B39: 4) 계정 중도 해지 시, 갑은 해지 통보 당일까지 포함하여 아래 기준으로 일할 계산하여 을에게 로열티를 청구한다.
B40: * 일별 로열티 금액 : 3D 홈 플래너 소프트웨어 계정 1개당 1,000원 (VAT별도, 30일을 기준으로 산정하여 일할 계산)
B41: =" * 25년 영업지원제도에 의거, "&#REF!&" 사용분에 대해 50% 본사지원" -> #REF! | L41: 체크
B42: 지원 후 금액 : 계정당 일별 사용료 500원 (VAT별도)
B43: 5) 계약 이후 을이 신규 계정을 신청했을 경우, 갑은 을의 신청한 월에 한하여 로열티를 무료로 제공한다.
B45: 제6조 [정보 공유]
B46: 1) 갑은 을이 본 계약상 권리의 이용을 위해 필요한 자료와 정보를 요청하는 경우, 특별한 사정이 없는 한 가능한 범위 내에서 상호 협의한
B47: 일정에 따라 이를 제공하여야 한다.
B48: 2) 을은 갑의 승인을 득한 경우에 한해 갑이 제공한 자료를 제3자에게 공개할 수 있다.
B50: 제7조 [지식재산권 등]
B51: 1) 본 계약상 또는 본 계약과 관련하여 갑이 제공하는 도면, 결과물, 제작물 등의 지식재산권은 당사자들 사이에 특별한 약정이 없는 한
B52: 갑의 소유로 하며, 을은 이를 대리점 계약의 목적 외 다른 용도로 사용해서는 아니 된다.
B53: 2) 대리점 계약 해지 시, 계약 기간 내의 제작했던 대리점의 설계도면, 가구 배치가 되어있는 창작 업무의 결과물/제작물 등의 지식재산권을
...

Sheet 동반성장 및 청렴서약서
A3: 동반성장 및 청렴 실천 서약서
A6: 당사는 주식회사 일룸(이하 ‘회사’라고 함)과 거래를 함에 있어, 신뢰를 바탕으로 자율적인 공정거래
A7: 질서 확립 및 동반성장을 위해 당사의 임직원과 대리인은 다음의 사항을 서약합니다
B10: 1. 당사는 입찰, 계약체결 및 계약이행과정에서 회사의 임직원에게 직·간접적으로 금품이나 향응 등 (친인석 등에 대한 부정한
B11: 취업 제공 포함)의 뇌물 또는 경제적 이익을 제공하기로 약속하거나 제공하지 않겠습니다.
B13: 2. 당사는 회사의 윤리규정 및 당사의 윤리규정에 위반되는 금품 또는 향응, 접대 및 편의를 제공하거나 받지 않겠으며
B14: 금전차용, 담보제공 등 경제적 이익을 제공하거나 요구하지 않겠습니다. 당사는 게약체결 및 이행과정에서 회사 및 당사
B15: 임직원의 비리행위 또는 불공정행위를 발견한 경우 회사에 제보하도록 하겠습니다.
B17: 3. 당사는 공정거래에 관한 법률, 하도급거래 공정화에 관한 법률, 기타 뇌물 방지 관련 법령, 부정경쟁방지 및 영업비밀보호에
B18: 관한 법률 등 관련 법규를 준수하고 담합, 허위자료 제출 등의 불공정행위를 하지 않으며 공정하고 투명한 계약이행 및
B19: 기업 경영을 위하여 노력하겠습니다.
B21: 4. 당사는 임ㆍ직원이 거래관계에서 금품, 향응 등을 제공하거나 담합 등 불공정행위를 하지 않도록 하는 윤리강령과 실전지침 및
B22: 내부비리 제보자에 대해서도 일체의 불이익 처분을 하지 않는 사규를 제정토록 노력하겠습니다.당사는 회사가 시행하는 윤리경영,
B23: 준법경영 프로그램을 이해 및 존중하며 필요한 경우 임직원 교육 등 조치를 강구할 것입니다.
B25: 5. 당사는 계약이행과정에서 알게 된 성과물 등 특정 정보를 임의로 제3자에게 제공 또는 누설하지 않으며, 공정한 직무수행을 방해하는
... B31: 것이며 이에 대하여 민·형사상 일체의 이의를 제기하지 않겠습니다.
C34: =#REF! -> #REF!
B37: "공급업자" | C37: 상호 : | D37: =#REF! -> #REF!
C38: 주소 : | D38: =#REF! -> #REF!
C39: 대표 : | D39: =#REF! -> #REF! | H39: (인)
B42: "대리점" | C42: 상호 : | D42: =#REF! -> #REF! | K42: 체크
C43: 주소 : | D43: =#REF! -> #REF! | K43: 체크
C44: 대표 : | D44: =#REF! -> #REF! | H44: (인) | K44: 체크

Sheet 계약체결용
B3: 대리점명 | C3: 대리점유형 | D3: 24년 거래보증금 설정 | G3: 24거래보증금 | H3: 사업자명 | I3: 사업자번호 | J3: 대표 | K3: 주소 | L3: 계약시작 | M3: 계약만료 | N3: 계약기간 | O3: 메일
B4: 강릉4 | C4: B/S-Shop | D4: 현금 | E4: 이천만원 | F4: 20,000,000원 | G4: =E4&" (\"&F4&")" -> 이천만원 (\20,000,000원) | H4: 일룸강릉브랜드샵(주) | I4: 201-86-45638 | J4: 최 종 섭 | K4: 강원 강릉시 율곡로 3190 | L4: 2024년 4월 1일 | M4: 2025년 3월 31일 | N4: 2024년 4월 1일 ~ 2025년 3월 31일 | O4: gniloom@daum.net
B5: 거제3 | C5: B/S-Shop | D5: 현금 | E5: 이천만원 | F5: 20,000,000원 | G5: =E5&" (\"&F5&")" -> 이천만원 (\20,000,000원) | H5: (주)일룸거제 | I5: 612-81-48524 | J5: 김 임 숙 | K5: 경남 거제시 수월동 1043-47 | L5: 2024년 4월 1일 | M5: 2025년 3월 31일 | N5: 2024년 4월 1일 ~ 2025년 3월 31일 | O5: topnsj@naver.com
B6: 경주4 | C6: B/S-Shop | D6: 현금 | E6: 이천만원 | F6: 20,000,000원 | G6: =E6&" (\"&F6&")" -> 이천만원 (\20,000,000원) | H6: 그린퍼니처 | I6: 505-09-65796 | J6: 신 도 철 | K6: 경북 경주시 원화로468, b동 | L6: 2024년 4월 1일 | M6: 2025년 3월 31일 | N6: 2024년 4월 1일 ~ 2025년 3월 31일 | O6: ch9000@hanmail.net
B7: 구리남양주2 | C7: B/S-Shop | D7: 보증보험 | E7: 이천만원 | F7: 20,000,000원 | G7: =E7&" (\"&F7&")" -> 이천만원 (\20,000,000원) | H7: 일룸 구리남양주점 | I7: 228-27-00532 | J7: 박 상 근 | K7: 경기 구리시 경춘로 286, 2,3,4층 | L7: 2024년 4월 1일 | M7: 2025년 3월 31일 | N7: 2024년 4월 1일 ~ 2025년 3월 31일 | O7: xoghksdls21@naver.com
B8: 구미5 | C8: B/S-Shop | D8: 현금 | E8: 이천만원 | F8: 20,000,000원 | G8: =E8&" (\"&F8&")" -> 이천만원 (\20,000,000원) | H8: 일룸 가구 구미점 | I8: 283-05-01540 | J8: 김관우, 김동윤, 박정애 | K8: 경북 구미시 산업로28길 4 | L8: 2024년 4월 1일 | M8: 2025년 3월 31일 | N8: 2024년 4월 1일 ~ 2025년 3월 31일 | O8: ktongyun@hanmail.net
B9: 김포5 | C9: B/S-Shop | D9: 현금 | E9: 이천만원 | F9: 20,000,000원 | G9: =E9&" (\"&F9&")" -> 이천만원 (\20,000,000원) | H9: 일룸김포점 | I9: 137-17-39033 | J9: 장 미 영 | K9: 경기 김포시 풍무동 27-4 1,2층 | L9: 2024년 4월 1일 | M9: 2025년 3월 31일 | N9: 2024년 4월 1일 ~ 2025년 3월 31일 | O9: kanges232@naver.com
B10: 김해2 | C10: B/S-Shop | D10: 현금 | E10: 이천만원 | F10: 20,000,000원 | G10: =E10&" (\"&F10&")" -> 이천만원 (\20,000,000원) | H10: 일룸 김해브랜드샵 | I10: 615-17-27736 | J10: 박 효 정 | K10: 경남 김해시 풍유동 47-3 | L10: 2024년 4월 1일 | M10: 2025년 3월 31일 | N10: 2024년 4월 1일 ~ 2025년 3월 31일 | O10: iloomju@naver.com
B11: 달서5 | C11: B/S-Shop | D11: 보증보험 | E11: 이천만원 | F11: 20,000,000원 | G11: =E11&" (\"&F11&")" -> 이천만원 (\20,000,000원) | H11: 일룸달서프리미엄샵 | I11: 514-19-58959 | J11: 서 미 경 | K11: 대구 달서구 조암로 200(유천동) | L11: 2024년 4월 1일 | M11: 2025년 3월 31일 | N11: 2024년 4월 1일 ~ 2025년 3월 31일 | O11: heraseo219@naver.com
B12: 덕진2 | C12: B/S-Shop | D12: 현금 | E12: 이천만원 | F12: 20,000,000원 | G12: =E12&" (\"&F12&")" -> 이천만원 (\20,000,000원) | H12: 일룸 덕진점 | I12: 418-06-94448 | J12: 유 수 정 | K12: 전북 전주시 덕진구 송천중앙로 6 | L12: 2024년 4월 1일 | M12: 2025년 3월 31일 | N12: 2024년 4월 1일 ~ 2025년 3월 31일 | O12: eiloom@nate.com
B13: 마산6 | C13: B/S-Shop | D13: 현금 | E13: 이천만원 | F13: 20,000,000원 | G13: =E13&" (\"&F13&")" -> 이천만원 (\20,000,000원) | H13: 퍼시스스마트OPC(극동) | I13: 608-47-60393 | J13: 강 호 근 | K13: 경남 창원시 마산회원구 봉양로 187(봉암동) | L13: 2024년 4월 1일 | M13: 2025년 3월 31일 | N13: 2024년 4월 1일 ~ 2025년 3월 31일 | O13: smartopc1@naver.com
B14: 봉선5 | C14: B/S-Shop | D14: 보증보험 | E14: 이천만원 | F14: 20,000,000원 | G14: =E14&" (\"&F14&")" -> 이천만원 (\20,000,000원) | H14: 주식회사 일룸앤데스커 | I14: 408-88-02821 | J14: 조 평 호 | K14: 광주광역시 남구 봉선로 16 (주월동) 1층 | L14: 2024년 4월 1일 | M14: 2025년 3월 31일 | N14: 2024년 4월 1일 ~ 2025년 3월 31일 | O14: gagu0512@naver.com
B15: 부천3 | C15: B/S-Shop | D15: 현금 | E15: 이천만원 | F15: 20,000,000원 | G15: =E15&" (\"&F15&")" -> 이천만원 (\20,000,000원) | H15: 일룸 부천점 | I15: 313-36-00088 | J15: 최 민 영 | K15: 경기 부천시 길주로 462 | L15: 2024년 4월 1일 | M15: 2024년 12월 31일 | N15: 2024년 4월 1일 ~ 2024년 12월 31일 | O15: iloombc@naver.com
... B62: 롯데청량리 | C62: 투자형 B-Shop (입점) | D62: 현금 | E62: 이천만원 | F62: 20,000,000원 | G62: =E62&" (\"&F62&")" -> 이천만원 (\20,000,000원) | H62: (주)아이룸텍 | I62: 778-87-02591 | J62: 오 중 현 | K62: 서울 중랑구 동일로 898 | L62: 2024년 4월 1일 | M62: 2025년 2월 28일 | N62: 2024년 4월 1일 ~ 2025년 2월 28일 | O62: to7887@nate.com
B63: 롯데평촌 | C63: 투자형 B-Shop (입점) | D63: 현금 | E63: 이천만원 | F63: 20,000,000원 | G63: =E63&" (\"&F63&")" -> 이천만원 (\20,000,000원) | H63: 일룸평촌전시장 | I63: 138-10-79418 | J63: 황 봉 국 | K63: 경기도 안양시 동안구 시민대로 180, 6층(호계동, 롯데백화점 평촌점) | L63: 2024년 4월 1일 | M63: 2024년 8월 31일 | N63: =L63&" ~ "&M63 -> 2024년 4월 1일 ~ 2024년 8월 31일 | O63: bkhwang4600@naver.com
B64: 송도4 | C64: 투자형 B-Shop (입점) | D64: 보증보험 | E64: 이천만원 | F64: 20,000,000원 | G64: =E64&" (\"&F64&")" -> 이천만원 (\20,000,000원) | H64: (주)알루컴 인천점 | I64: 105-85-41701 | J64: 이 종 균 | K64: 인천 남동구 인주대로 644 | L64: 2024년 4월 1일 | M64: 2024년 8월 31일 | N64: 2024년 4월 1일 ~ 2024년 8월 31일 | O64: ff1001@nate.com
B65: 스타필드고양 | C65: 투자형 B-Shop (입점) | D65: 보증보험 | E65: 이천만원 | F65: 20,000,000원 | G65: =E65&" (\"&F65&")" -> 이천만원 (\20,000,000원) | H65: 페드라(일룸 스타필드고양) | I65: 417-10-72598 | J65: 안 중 우 | K65: 경기도 고양시 덕양구 고양대로 1955, b1층 | L65: 2024년 4월 1일 | M65: 2025년 3월 31일 | N65: 2024년 4월 1일 ~ 2025년 3월 31일 | O65: ajw7609@naver.com
B66: 스타필드수원(6층) | C66: 투자형 B-Shop (입점) | D66: 현금 | E66: 이천만원 | F66: 20,000,000원 | G66: =E66&" (\"&F66&")" -> 이천만원 (\20,000,000원) | H66: 주식회사 일룸수원중앙점 | I66: 609-87-00128 | J66: 석 옥 련 | K66: 경기 수원시 장안구 수성로 175, 6층 6210호(정자동, 스타필드수원) | L66: 2024년 4월 1일 | M66: 2025년 3월 31일 | N66: 2024년 4월 1일 ~ 2025년 3월 31일 | O66: do0815@hanmail.net
B67: 스타필드수원키즈(3층) | C67: 투자형 B-Shop (입점) | D67: 현금 | E67: 이천만원 | F67: 20,000,000원 | G67: =E67&" (\"&F67&")" -> 이천만원 (\20,000,000원) | H67: 주식회사 일룸수원중앙점 | I67: 609-87-00128 | J67: 석 옥 련 | K67: 경기 수원시 장안구 수성로 175, 6층 6210호(정자동, 스타필드수원) | L67: 2024년 4월 1일 | M67: 2025년 3월 31일 | N67: 2024년 4월 1일 ~ 2025년 3월 31일 | O67: do0815@hanmail.net
B68: 신세계대전 | C68: 투자형 B-Shop (입점) | D68: 현금 | E68: 이천만원 | F68: 20,000,000원 | G68: =E68&" (\"&F68&")" -> 이천만원 (\20,000,000원) | H68: 일룸 도안3점 | I68: 314-27-63783 | J68: 류 대 열 | K68: 대전 서구 가수원동 1061 리더스프라자 B동 2~3층 | L68: 2024년 4월 1일 | M68: 2024년 5월 31일 | N68: 2024년 4월 1일 ~ 2024년 5월 31일 | O68: kianadol@naver.com
B69: 신세계시흥 | C69: 투자형 B-Shop (입점) | D69: 현금 | E69: 이천만원 | F69: 20,000,000원 | G69: =E69&" (\"&F69&")" -> 이천만원 (\20,000,000원) | H69: 일룸신세계시흥점 | I69: 133-11-84607 | J69: 정 혜 진 | K69: 경기도 시흥시 서해안로 699, 2층 2921호(정왕동, 시흥프리미엄아울렛) | L69: 2024년 4월 1일 | M69: 2024년 5월 31일 | N69: 2024년 4월 1일 ~ 2024년 5월 31일 | O69: snsla0325@naver.com
B70: 신세계파주2 | C70: 투자형 B-Shop (입점) | D70: 보증보험 | E70: 이천만원 | F70: 20,000,000원 | G70: =E70&" (\"&F70&")" -> 이천만원 (\20,000,000원) | H70: 토호드 | I70: 837-15-00255 | J70: 안 중 협 | K70: 경기도 고양시 일산동구 월드고양로 102-33, 2층 | L70: 2024년 4월 1일 | M70: 2025년 3월 31일 | N70: 2024년 4월 1일 ~ 2025년 3월 31일 | O70: garnet212@naver.com

Sheet 2503기준유통망
B1: 2503대리점 | C1: 영업담당 | D1: 24 유통망구분 | E1: 특이사항 | F1: 25체결기준 | G1: 25계약 챙길부분 | H1: 계약체결
B2: 대전도안3 | C2: 김지수 | D2: =VLOOKUP(B2,계약체결용!$B:$C,2,0) -> 투자형 B-Shop (로드) | F2: =D2 -> 투자형 B-Shop (로드) | J2: 행 레이블 | K2: 개수 : 계약체결
B3: 롯데미아 | C3: 김지수 | D3: =VLOOKUP(B3,계약체결용!$B:$C,2,0) -> #N/A | E3: 새로생김 | F3: b/s-shop (입점) | G3: 임대차 | J3: 김지수 | K3: 7
B4: 롯데청량리 | C4: 김지수 | D4: =VLOOKUP(B4,계약체결용!$B:$C,2,0) -> 투자형 B-Shop (입점) | E4: 유형변경 | F4: b/s-shop (입점) | G4: 임대차 | J4: 대전도안3
B5: 서대전3 | C5: 김지수 | D5: =VLOOKUP(B5,계약체결용!$B:$C,2,0) -> B/S-Shop | F5: =D5 -> B/S-Shop | H5: ㅇ | J5: 롯데미아
B6: 서산3 | C6: 김지수 | D6: =VLOOKUP(B6,계약체결용!$B:$C,2,0) -> B/S-Shop | F6: =D6 -> B/S-Shop | H6: ㅇ | J6: 롯데청량리
B7: 세종2 | C7: 김지수 | D7: =VLOOKUP(B7,계약체결용!$B:$C,2,0) -> B/S-Shop | F7: =D7 -> B/S-Shop | H7: ㅇ | J7: 서대전3 | K7: 1
B8: 신세계대전(팝업) | C8: 김지수 | D8: =VLOOKUP(B8,계약체결용!$B:$C,2,0) -> #N/A | E8: 왜지 | F8: 투자형 B-Shop (입점) | G8: 임대차 | J8: 서산3 | K8: 1
B9: 천안불당3 | C9: 김지수 | D9: =VLOOKUP(B9,계약체결용!$B:$C,2,0) -> B/S-Shop | F9: =D9 -> B/S-Shop | H9: ㅇ | J9: 세종2 | K9: 1
B10: 천안신방3 | C10: 김지수 | D10: =VLOOKUP(B10,계약체결용!$B:$C,2,0) -> 투자형 B-Shop (로드) | F10: =D10 -> 투자형 B-Shop (로드) | H10: ㅇ | J10: 신세계대전(팝업)
B11: 청남3 | C11: 김지수 | D11: =VLOOKUP(B11,계약체결용!$B:$C,2,0) -> B/S-Shop | F11: =D11 -> B/S-Shop | H11: ㅇ | J11: 천안불당3 | K11: 1
B12: 청주6 | C12: 김지수 | D12: =VLOOKUP(B12,계약체결용!$B:$C,2,0) -> B/S-Shop | F12: =D12 -> B/S-Shop | J12: 천안신방3 | K12: 1
B13: 청주중앙4 | C13: 김지수 | D13: =VLOOKUP(B13,계약체결용!$B:$C,2,0) -> B/S-Shop | F13: =D13 -> B/S-Shop | H13: ㅇ | J13: 청남3 | K13: 1
B14: 경주4 | C14: 김효진 | D14: =VLOOKUP(B14,계약체결용!$B:$C,2,0) -> B/S-Shop | F14: =D14 -> B/S-Shop | H14: ㅇ | J14: 청주6
B15: 구미5 | C15: 김효진 | D15: =VLOOKUP(B15,계약체결용!$B:$C,2,0) -> B/S-Shop | F15: =D15 -> B/S-Shop | H15: ㅇ | J15: 청주중앙4 | K15: 1
B16: 달서5 | C16: 김효진 | D16: =VLOOKUP(B16,계약체결용!$B:$C,2,0) -> B/S-Shop | F16: =D16 -> B/S-Shop | H16: ㅇ | J16: 김효진 | K16: 8
B17: 수성5 | C17: 김효진 | D17: =VLOOKUP(B17,계약체결용!$B:$C,2,0) -> B/S-Shop | F17: =D17 -> B/S-Shop | H17: ㅇ | J17: 경주4 | K17: 1
B18: 스타필드고양 | C18: 김효진 | D18: =VLOOKUP(B18,계약체결용!$B:$C,2,0) -> 투자형 B-Shop (입점) | F18: =D18 -> 투자형 B-Shop (입점) | H18: ㅇ | J18: 구미5 | K18: 1
B19: 신세계파주2 | C19: 김효진 | D19: =VLOOKUP(B19,계약체결용!$B:$C,2,0) -> 투자형 B-Shop (입점) | F19: =D19 -> 투자형 B-Shop (입점) | G19: 임대차 | J19: 달서5 | K19: 1
B20: 안동5 | C20: 김효진 | D20: =VLOOKUP(B20,계약체결용!$B:$C,2,0) -> B/S-Shop | F20: =D20 -> B/S-Shop | H20: ㅇ | J20: 수성5 | K20: 1
B21: 일산킨텍스 | C21: 김효진 | D21: =VLOOKUP(B21,계약체결용!$B:$C,2,0) -> B/S-Shop | F21: =D21 -> B/S-Shop | J21: 스타필드고양 | K21: 1
B22: 태릉묵동6 | C22: 김효진 | D22: =VLOOKUP(B22,계약체결용!$B:$C,2,0) -> B/S-Shop | F22: =D22 -> B/S-Shop | J22: 신세계파주2
B23: 포항2 | C23: 김효진 | D23: =VLOOKUP(B23,계약체결용!$B:$C,2,0) -> B/S-Shop | F23: =D23 -> B/S-Shop | H23: ㅇ | J23: 안동5 | K23: 1
B24: 포항중앙2 | C24: 김효진 | D24: =VLOOKUP(B24,계약체결용!$B:$C,2,0) -> B/S-Shop | F24: =D24 -> B/S-Shop | H24: ㅇ | J24: 일산킨텍스
B25: LXH목동 | C25: 서다솔 | D25: =VLOOKUP(B25,계약체결용!$B:$C,2,0) -> 투자형 B-Shop (로드) | F25: =D25 -> 투자형 B-Shop (로드) | G25: 임대차 | H25: ㅇ | J25: 태릉묵동6
B26: 구리남양주2 | C26: 서다솔 | D26: =VLOOKUP(B26,계약체결용!$B:$C,2,0) -> B/S-Shop | F26: =D26 -> B/S-Shop | H26: ㅇ | J26: 포항2 | K26: 1
B27: 김포5 | C27: 서다솔 | D27: =VLOOKUP(B27,계약체결용!$B:$C,2,0) -> B/S-Shop | F27: =D27 -> B/S-Shop | H27: ㅇ | J27: 포항중앙2 | K27: 1
B28: 롯데영등포 | C28: 서다솔 | D28: =VLOOKUP(B28,계약체결용!$B:$C,2,0) -> #N/A | E28: 새로생김 | F28: b/s-shop (입점) | G28: 임대차 | H28: ㅇ | J28: 서다솔 | K28: 10
B29: 롯데인천(팝업) | C29: 서다솔 | D29: =VLOOKUP(B29,계약체결용!$B:$C,2,0) -> #N/A | E29: 새로생김 | F29: b/s-shop (입점) | G29: 임대차 | H29: ㅇ | J29: LXH목동 | K29: 1
B30: 부천3 | C30: 서다솔 | D30: =VLOOKUP(B30,계약체결용!$B:$C,2,0) -> B/S-Shop | F30: =D30 -> B/S-Shop | H30: ㅇ | J30: 구리남양주2 | K30: 1
B31: 송도4 | C31: 서다솔 | D31: =VLOOKUP(B31,계약체결용!$B:$C,2,0) -> 투자형 B-Shop (입점) | F31: =D31 -> 투자형 B-Shop (입점) | G31: 임대차 | H31: ㅇ | J31: 김포5 | K31: 1
B32: 신세계시흥2 | C32: 서다솔 | D32: =VLOOKUP(B32,계약체결용!$B:$C,2,0) -> #N/A | E32: 새로생김 | F32: 투자형 B-Shop (입점) | J32: 롯데영등포 | K32: 1
B33: 의정부8 | C33: 서다솔 | D33: =VLOOKUP(B33,계약체결용!$B:$C,2,0) -> B/S-Shop | F33: =D33 -> B/S-Shop | H33: ㅇ | J33: 롯데인천(팝업) | K33: 1
B34: 인천검단 | C34: 서다솔 | D34: =VLOOKUP(B34,계약체결용!$B:$C,2,0) -> 투자형 B-Shop (로드) | F34: =D34 -> 투자형 B-Shop (로드) | H34: ㅇ | J34: 부천3 | K34: 1
B35: 인천중앙2 | C35: 서다솔 | D35: =VLOOKUP(B35,계약체결용!$B:$C,2,0) -> B/S-Shop | F35: =D35 -> B/S-Shop | H35: ㅇ | J35: 송도4 | K35: 1
B36: LXH창원 | C36: 이광호 | D36: =VLOOKUP(B36,계약체결용!$B:$C,2,0) -> 투자형 B-Shop (로드) | F36: =D36 -> 투자형 B-Shop (로드) | G36: 임대차 | J36: 신세계시흥2
B37: 거제4 | C37: 이광호 | D37: =VLOOKUP(B37,계약체결용!$B:$C,2,0) -> #N/A | E37: 새로생김 | F37: B/S-Shop | H37: ㅇ | J37: 의정부8 | K37: 1
B38: 김해2 | C38: 이광호 | D38: =VLOOKUP(B38,계약체결용!$B:$C,2,0) -> B/S-Shop | F38: =D38 -> B/S-Shop | J38: 인천검단 | K38: 1
B39: 롯데광복2 | C39: 이광호 | D39: =VLOOKUP(B39,계약체결용!$B:$C,2,0) -> #N/A | E39: 새로생김 | F39: b/s-shop (입점) | H39: ㅇ | J39: 인천중앙2 | K39: 1
B40: 롯데동부산2 | C40: 이광호 | D40: =VLOOKUP(B40,계약체결용!$B:$C,2,0) -> 투자형 B-Shop (입점) | F40: =D40 -> 투자형 B-Shop (입점) | H40: ㅇ | J40: 이광호 | K40: 8
...

Sheet 26년계약체결용
B2: 대리점명 | C2: 대리점유형 | D2: 26년 거래보증금 설정 | G2: 26거래보증금 | H2: 사업자명 | I2: 사업자번호 | J2: 대표 | K2: 주소 | L2: 계약시작 | M2: 계약만료 | N2: 계약기간 | O2: 메일
B3: 거제4 | C3: =VLOOKUP(B3,'2603실제'!$D:$E,2,0) -> 일반BS | D3: 현금 | E3: 이천만원 | F3: 20,000,000원 | G3: =E3&" (\"&F3&")" -> 이천만원 (\20,000,000원) | H3: =VLOOKUP(B3,'25년계약체결리스트'!$B:$K,7,0) -> 일룸 거제점 | I3: =VLOOKUP(B3,'25년계약체결리스트'!$B:$O,8,0) -> 178-73-00699 | J3: =VLOOKUP(B3,'25년계약체결리스트'!$B:$O,9,0) -> 안 율 | K3: =VLOOKUP(B3,'25년계약체결리스트'!$B:$O,10,0) -> 경상남도 거제시 수양로 454-40, 2층(수월동) | L3: 2026년 4월 1일 | M3: 2027년 3월 31일 | N3: =L3&" ~ "&M3 -> 2026년 4월 1일 ~ 2027년 3월 31일 | O3: =VLOOKUP(B3,'25년계약체결리스트'!$B:$O,14,0) -> ld5yul@hanmail.net
B4: 경주4 | C4: =VLOOKUP(B4,'2603실제'!$D:$E,2,0) -> 일반BS | D4: 현금 | E4: 이천만원 | F4: 20,000,000원 | G4: =E4&" (\"&F4&")" -> 이천만원 (\20,000,000원) | H4: =VLOOKUP(B4,'25년계약체결리스트'!$B:$K,7,0) -> 그린퍼니처 | I4: =VLOOKUP(B4,'25년계약체결리스트'!$B:$O,8,0) -> 505-09-65796 | J4: =VLOOKUP(B4,'25년계약체결리스트'!$B:$O,9,0) -> 신 도 철 | K4: =VLOOKUP(B4,'25년계약체결리스트'!$B:$O,10,0) -> 경북 경주시 원화로468, b동 | L4: 2026년 4월 1일 | M4: 2027년 3월 31일 | N4: =L4&" ~ "&M4 -> 2026년 4월 1일 ~ 2027년 3월 31일 | O4: =VLOOKUP(B4,'25년계약체결리스트'!$B:$O,14,0) -> ch9000@hanmail.net
B5: 구미5 | C5: =VLOOKUP(B5,'2603실제'!$D:$E,2,0) -> 일반BS | D5: 현금 | E5: 이천만원 | F5: 20,000,000원 | G5: =E5&" (\"&F5&")" -> 이천만원 (\20,000,000원) | H5: =VLOOKUP(B5,'25년계약체결리스트'!$B:$K,7,0) -> 일룸 가구 구미점 | I5: =VLOOKUP(B5,'25년계약체결리스트'!$B:$O,8,0) -> 283-05-01540 | J5: =VLOOKUP(B5,'25년계약체결리스트'!$B:$O,9,0) -> 김관우, 김동윤, 박정애 | K5: =VLOOKUP(B5,'25년계약체결리스트'!$B:$O,10,0) -> 경북 구미시 산업로28길 4 | L5: 2026년 4월 1일 | M5: 2027년 3월 31일 | N5: =L5&" ~ "&M5 -> 2026년 4월 1일 ~ 2027년 3월 31일 | O5: =VLOOKUP(B5,'25년계약체결리스트'!$B:$O,14,0) -> ktongyun@hanmail.net
B6: 김포5 | C6: =VLOOKUP(B6,'2603실제'!$D:$E,2,0) -> 일반BS | D6: 현금 | E6: 이천만원 | F6: 20,000,000원 | G6: =E6&" (\"&F6&")" -> 이천만원 (\20,000,000원) | H6: =VLOOKUP(B6,'25년계약체결리스트'!$B:$K,7,0) -> 일룸김포점 | I6: =VLOOKUP(B6,'25년계약체결리스트'!$B:$O,8,0) -> 137-17-39033 | J6: =VLOOKUP(B6,'25년계약체결리스트'!$B:$O,9,0) -> 장 미 영 | K6: =VLOOKUP(B6,'25년계약체결리스트'!$B:$O,10,0) -> 경기 김포시 풍무동 27-4 1,2층 | L6: 2026년 4월 1일 | M6: 2027년 3월 31일 | N6: =L6&" ~ "&M6 -> 2026년 4월 1일 ~ 2027년 3월 31일 | O6: =VLOOKUP(B6,'25년계약체결리스트'!$B:$O,14,0) -> kanges232@naver.com
B7: 김해2 | C7: =VLOOKUP(B7,'2603실제'!$D:$E,2,0) -> 일반BS | D7: 현금 | E7: 이천만원 | F7: 20,000,000원 | G7: =E7&" (\"&F7&")" -> 이천만원 (\20,000,000원) | H7: =VLOOKUP(B7,'25년계약체결리스트'!$B:$K,7,0) -> 일룸 김해브랜드샵 | I7: =VLOOKUP(B7,'25년계약체결리스트'!$B:$O,8,0) -> 615-17-27736 | J7: =VLOOKUP(B7,'25년계약체결리스트'!$B:$O,9,0) -> 박 효 정 | K7: =VLOOKUP(B7,'25년계약체결리스트'!$B:$O,10,0) -> 경남 김해시 풍유동 47-3 | L7: 2026년 4월 1일 | M7: 2027년 3월 31일 | N7: =L7&" ~ "&M7 -> 2026년 4월 1일 ~ 2027년 3월 31일 | O7: =VLOOKUP(B7,'25년계약체결리스트'!$B:$O,14,0) -> iloomju@naver.com
B8: 달서5 | C8: =VLOOKUP(B8,'2603실제'!$D:$E,2,0) -> 일반BS | D8: 현금 | E8: 이천만원 | F8: 20,000,000원 | G8: =E8&" (\"&F8&")" -> 이천만원 (\20,000,000원) | H8: =VLOOKUP(B8,'25년계약체결리스트'!$B:$K,7,0) -> 일룸달서프리미엄샵 | I8: =VLOOKUP(B8,'25년계약체결리스트'!$B:$O,8,0) -> 514-19-58959 | J8: =VLOOKUP(B8,'25년계약체결리스트'!$B:$O,9,0) -> 서 미 경 | K8: =VLOOKUP(B8,'25년계약체결리스트'!$B:$O,10,0) -> 대구 달서구 조암로 200(유천동) | L8: 2026년 4월 1일 | M8: 2027년 3월 31일 | N8: =L8&" ~ "&M8 -> 2026년 4월 1일 ~ 2027년 3월 31일 | O8: =VLOOKUP(B8,'25년계약체결리스트'!$B:$O,14,0) -> heraseo219@nate.com
B9: 덕진2 | C9: =VLOOKUP(B9,'2603실제'!$D:$E,2,0) -> 일반BS | D9: 현금 | E9: 이천만원 | F9: 20,000,000원 | G9: =E9&" (\"&F9&")" -> 이천만원 (\20,000,000원) | H9: =VLOOKUP(B9,'25년계약체결리스트'!$B:$K,7,0) -> 일룸 덕진점 | I9: =VLOOKUP(B9,'25년계약체결리스트'!$B:$O,8,0) -> 418-06-94448 | J9: =VLOOKUP(B9,'25년계약체결리스트'!$B:$O,9,0) -> 유 수 정 | K9: =VLOOKUP(B9,'25년계약체결리스트'!$B:$O,10,0) -> 전북 전주시 덕진구 송천중앙로 6 | L9: 2026년 4월 1일 | M9: 2027년 3월 31일 | N9: =L9&" ~ "&M9 -> 2026년 4월 1일 ~ 2027년 3월 31일 | O9: =VLOOKUP(B9,'25년계약체결리스트'!$B:$O,14,0) -> elioom@nate.com
B10: 마산6 | C10: =VLOOKUP(B10,'2603실제'!$D:$E,2,0) -> 일반BS | D10: 현금 | E10: 이천만원 | F10: 20,000,000원 | G10: =E10&" (\"&F10&")" -> 이천만원 (\20,000,000원) | H10: =VLOOKUP(B10,'25년계약체결리스트'!$B:$K,7,0) -> 퍼시스스마트OPC(극동) | I10: =VLOOKUP(B10,'25년계약체결리스트'!$B:$O,8,0) -> 608-47-60393 | J10: =VLOOKUP(B10,'25년계약체결리스트'!$B:$O,9,0) -> 강 호 근 | K10: =VLOOKUP(B10,'25년계약체결리스트'!$B:$O,10,0) -> 경남 창원시 마산회원구 봉양로 187(봉암동) | L10: 2026년 4월 1일 | M10: 2027년 3월 31일 | N10: =L10&" ~ "&M10 -> 2026년 4월 1일 ~ 2027년 3월 31일 | O10: =VLOOKUP(B10,'25년계약체결리스트'!$B:$O,14,0) -> smartopc@naver.com
B11: 봉선5 | C11: =VLOOKUP(B11,'2603실제'!$D:$E,2,0) -> 일반BS | D11: 현금 | E11: 이천만원 | F11: 20,000,000원 | G11: =E11&" (\"&F11&")" -> 이천만원 (\20,000,000원) | H11: =VLOOKUP(B11,'25년계약체결리스트'!$B:$K,7,0) -> 주식회사 일룸앤데스커 | I11: =VLOOKUP(B11,'25년계약체결리스트'!$B:$O,8,0) -> 408-88-02821 | J11: =VLOOKUP(B11,'25년계약체결리스트'!$B:$O,9,0) -> 조 평 호 | K11: =VLOOKUP(B11,'25년계약체결리스트'!$B:$O,10,0) -> 광주광역시 남구 봉선로 16 (주월동) 1층 | L11: 2026년 4월 1일 | M11: 2027년 3월 31일 | N11: =L11&" ~ "&M11 -> 2026년 4월 1일 ~ 2027년 3월 31일 | O11: =VLOOKUP(B11,'25년계약체결리스트'!$B:$O,14,0) -> gagu0512@naver.com
B12: 부천3 | C12: =VLOOKUP(B12,'2603실제'!$D:$E,2,0) -> 일반BS | D12: 현금 | E12: 이천만원 | F12: 20,000,000원 | G12: =E12&" (\"&F12&")" -> 이천만원 (\20,000,000원) | H12: =VLOOKUP(B12,'25년계약체결리스트'!$B:$K,7,0) -> 일룸 부천점 | I12: =VLOOKUP(B12,'25년계약체결리스트'!$B:$O,8,0) -> 313-36-00088 | J12: =VLOOKUP(B12,'25년계약체결리스트'!$B:$O,9,0) -> 최 민 영 | K12: =VLOOKUP(B12,'25년계약체결리스트'!$B:$O,10,0) -> 경기 부천시 길주로 462 | L12: 2026년 4월 1일 | M12: 2026년 12월 31일 | N12: =L12&" ~ "&M12 -> 2026년 4월 1일 ~ 2026년 12월 31일 | O12: =VLOOKUP(B12,'25년계약체결리스트'!$B:$O,14,0) -> iloombc@naver.com
B13: 분당2 | C13: =VLOOKUP(B13,'2603실제'!$D:$E,2,0) -> 일반BS | D13: 현금 | E13: 이천만원 | F13: 20,000,000원 | G13: =E13&" (\"&F13&")" -> 이천만원 (\20,000,000원) | H13: =VLOOKUP(B13,'25년계약체결리스트'!$B:$K,7,0) -> 일룸분당점 | I13: =VLOOKUP(B13,'25년계약체결리스트'!$B:$O,8,0) -> 135-10-97912 | J13: =VLOOKUP(B13,'25년계약체결리스트'!$B:$O,9,0) -> 최 상 헌 | K13: =VLOOKUP(B13,'25년계약체결리스트'!$B:$O,10,0) -> 경기도 성남시 분당구 대왕판교로214 | L13: 2026년 4월 1일 | M13: 2027년 3월 31일 | N13: =L13&" ~ "&M13 -> 2026년 4월 1일 ~ 2027년 3월 31일 | O13: =VLOOKUP(B13,'25년계약체결리스트'!$B:$O,14,0) -> csh6797@naver.com
B14: 빛고을3 | C14: =VLOOKUP(B14,'2603실제'!$D:$E,2,0) -> 일반BS | D14: 현금 | E14: 이천만원 | F14: 20,000,000원 | G14: =E14&" (\"&F14&")" -> 이천만원 (\20,000,000원) | H14: =VLOOKUP(B14,'25년계약체결리스트'!$B:$K,7,0) -> 일룸빛고을점 | I14: =VLOOKUP(B14,'25년계약체결리스트'!$B:$O,8,0) -> 415-48-01330 | J14: =VLOOKUP(B14,'25년계약체결리스트'!$B:$O,9,0) -> 최 정 우 | K14: =VLOOKUP(B14,'25년계약체결리스트'!$B:$O,10,0) -> 광주광역시 광산구 하남대로 352, 3층(신가동) | L14: 2026년 4월 1일 | M14: 2027년 3월 31일 | N14: =L14&" ~ "&M14 -> 2026년 4월 1일 ~ 2027년 3월 31일 | O14: =VLOOKUP(B14,'25년계약체결리스트'!$B:$O,14,0) -> woowby@naver.com
B15: 서대전3 | C15: =VLOOKUP(B15,'2603실제'!$D:$E,2,0) -> 일반BS | D15: 현금 | E15: 이천만원 | F15: 20,000,000원 | G15: =E15&" (\"&F15&")" -> 이천만원 (\20,000,000원) | H15: =VLOOKUP(B15,'25년계약체결리스트'!$B:$K,7,0) -> 일룸서대전점2 | I15: =VLOOKUP(B15,'25년계약체결리스트'!$B:$O,8,0) -> 305-29-60452 | J15: =VLOOKUP(B15,'25년계약체결리스트'!$B:$O,9,0) -> 김 영 애 | K15: =VLOOKUP(B15,'25년계약체결리스트'!$B:$O,10,0) -> 대전 중구 중앙로 8 (문화동, 가구갤러리 8층) | L15: 2026년 4월 1일 | M15: 2027년 3월 31일 | N15: =L15&" ~ "&M15 -> 2026년 4월 1일 ~ 2027년 3월 31일 | O15: =VLOOKUP(B15,'25년계약체결리스트'!$B:$O,14,0) -> iloom7052@hanmail.net
B16: 서산4 | C16: =VLOOKUP(B16,'2603실제'!$D:$E,2,0) -> 일반BS | D16: 현금 | E16: 이천만원 | F16: 20,000,000원 | G16: =E16&" (\"&F16&")" -> 이천만원 (\20,000,000원) | H16: 일룸 서산점 | I16: 123-47-01118 | J16: 김 정 남 | K16: 충청남도 서산시 서해로 3449(석림동) | L16: 2026년 4월 1일 | M16: 2027년 3월 31일 | N16: =L16&" ~ "&M16 -> 2026년 4월 1일 ~ 2027년 3월 31일 | O16: =VLOOKUP(B16,'25년계약체결리스트'!$B:$O,14,0) -> #N/A
B17: 세종2 | C17: =VLOOKUP(B17,'2603실제'!$D:$E,2,0) -> 일반BS | D17: 현금 | E17: 이천만원 | F17: 20,000,000원 | G17: =E17&" (\"&F17&")" -> 이천만원 (\20,000,000원) | H17: =VLOOKUP(B17,'25년계약체결리스트'!$B:$K,7,0) -> 일룸 세종점 | I17: =VLOOKUP(B17,'25년계약체결리스트'!$B:$O,8,0) -> 760-33-00129 | J17: =VLOOKUP(B17,'25년계약체결리스트'!$B:$O,9,0) -> 박정나, 이상연 | K17: =VLOOKUP(B17,'25년계약체결리스트'!$B:$O,10,0) -> 세종 아름동 1313 정원타워 3,4층 | L17: 2026년 4월 1일 | M17: 2027년 3월 31일 | N17: =L17&" ~ "&M17 -> 2026년 4월 1일 ~ 2027년 3월 31일 | O17: =VLOOKUP(B17,'25년계약체결리스트'!$B:$O,14,0) -> iloomsejong2016@daum.net
B18: 수성5 | C18: =VLOOKUP(B18,'2603실제'!$D:$E,2,0) -> 일반BS | D18: 현금 | E18: 이천만원 | F18: 20,000,000원 | G18: =E18&" (\"&F18&")" -> 이천만원 (\20,000,000원) | H18: =VLOOKUP(B18,'25년계약체결리스트'!$B:$K,7,0) -> 일룸수성점 | I18: =VLOOKUP(B18,'25년계약체결리스트'!$B:$O,8,0) -> 502-21-75604 | J18: =VLOOKUP(B18,'25년계약체결리스트'!$B:$O,9,0) -> 조진희, 차인호 | K18: =VLOOKUP(B18,'25년계약체결리스트'!$B:$O,10,0) -> 대구 수성구 희망로 152 | L18: 2026년 4월 1일 | M18: 2027년 3월 31일 | N18: =L18&" ~ "&M18 -> 2026년 4월 1일 ~ 2027년 3월 31일 | O18: =VLOOKUP(B18,'25년계약체결리스트'!$B:$O,14,0) -> wlsl4258@hanmail.net
B19: 순천4 | C19: =VLOOKUP(B19,'2603실제'!$D:$E,2,0) -> 일반BS | D19: 현금 | E19: 이천만원 | F19: 20,000,000원 | G19: =E19&" (\"&F19&")" -> 이천만원 (\20,000,000원) | H19: =VLOOKUP(B19,'25년계약체결리스트'!$B:$K,7,0) -> 주식회사 일룸 | I19: =VLOOKUP(B19,'25년계약체결리스트'!$B:$O,8,0) -> 142-88-00388 | J19: =VLOOKUP(B19,'25년계약체결리스트'!$B:$O,9,0) -> 김 대 현 | K19: =VLOOKUP(B19,'25년계약체결리스트'!$B:$O,10,0) -> 전남 순천시 중앙로 118 | L19: 2026년 4월 1일 | M19: 2027년 3월 31일 | N19: =L19&" ~ "&M19 -> 2026년 4월 1일 ~ 2027년 3월 31일 | O19: =VLOOKUP(B19,'25년계약체결리스트'!$B:$O,14,0) -> popeyes2@hanmail.net
B20: 안동5 | C20: =VLOOKUP(B20,'2603실제'!$D:$E,2,0) -> 일반BS | D20: 현금 | E20: 이천만원 | F20: 20,000,000원 | G20: =E20&" (\"&F20&")" -> 이천만원 (\20,000,000원) | H20: =VLOOKUP(B20,'25년계약체결리스트'!$B:$K,7,0) -> 일룸안동점 | I20: =VLOOKUP(B20,'25년계약체결리스트'!$B:$O,8,0) -> 511-08-44988 | J20: =VLOOKUP(B20,'25년계약체결리스트'!$B:$O,9,0) -> 조현주, 박주홍 | K20: =VLOOKUP(B20,'25년계약체결리스트'!$B:$O,10,0) -> 경북 안동시 하이마로 151 | L20: 2026년 4월 1일 | M20: 2027년 3월 31일 | N20: =L20&" ~ "&M20 -> 2026년 4월 1일 ~ 2027년 3월 31일 | O20: =VLOOKUP(B20,'25년계약체결리스트'!$B:$O,14,0) -> amaxs@hanmail.net
B21: 안산상록수2 | C21: =VLOOKUP(B21,'2603실제'!$D:$E,2,0) -> 일반BS | D21: 현금 | E21: 이천만원 | F21: 20,000,000원 | G21: =E21&" (\"&F21&")" -> 이천만원 (\20,000,000원) | H21: =VLOOKUP(B21,'25년계약체결리스트'!$B:$K,7,0) -> 일룸안산상록수점 | I21: =VLOOKUP(B21,'25년계약체결리스트'!$B:$O,8,0) -> 207-04-55609 | J21: =VLOOKUP(B21,'25년계약체결리스트'!$B:$O,9,0) -> 노 수 민 | K21: =VLOOKUP(B21,'25년계약체결리스트'!$B:$O,10,0) -> 경기 안산시 상록구 용신로 451-1(본오동,1,2층) | L21: 2026년 4월 1일 | M21: 2026년 9월 16일 | N21: =L21&" ~ "&M21 -> 2026년 4월 1일 ~ 2026년 9월 16일 | O21: =VLOOKUP(B21,'25년계약체결리스트'!$B:$O,14,0) -> wish2199@naver.com
B22: 양산3 | C22: =VLOOKUP(B22,'2603실제'!$D:$E,2,0) -> 일반BS | D22: 현금 | E22: 이천만원 | F22: 20,000,000원 | G22: =E22&" (\"&F22&")" -> 이천만원 (\20,000,000원) | H22: =VLOOKUP(B22,'25년계약체결리스트'!$B:$K,7,0) -> 일룸양산점 | I22: =VLOOKUP(B22,'25년계약체결리스트'!$B:$O,8,0) -> 463-03-00712 | J22: =VLOOKUP(B22,'25년계약체결리스트'!$B:$O,9,0) -> 남 명 현 | K22: =VLOOKUP(B22,'25년계약체결리스트'!$B:$O,10,0) -> 경남 양산시 물금읍 황산로 497 | L22: 2026년 4월 1일 | M22: 2027년 3월 31일 | N22: =L22&" ~ "&M22 -> 2026년 4월 1일 ~ 2027년 3월 31일 | O22: =VLOOKUP(B22,'25년계약체결리스트'!$B:$O,14,0) -> godid56@nate.com
B23: 연제4 | C23: =VLOOKUP(B23,'2603실제'!$D:$E,2,0) -> 일반BS | D23: 현금 | E23: 이천만원 | F23: 20,000,000원 | G23: =E23&" (\"&F23&")" -> 이천만원 (\20,000,000원) | H23: =VLOOKUP(B23,'25년계약체결리스트'!$B:$K,7,0) -> (주)일룸연제점 | I23: =VLOOKUP(B23,'25년계약체결리스트'!$B:$O,8,0) -> 388-87-01424 | J23: =VLOOKUP(B23,'25년계약체결리스트'!$B:$O,9,0) -> 이 철 희 | K23: =VLOOKUP(B23,'25년계약체결리스트'!$B:$O,10,0) -> 부산 연제구 거제대로 297, 2~3층 | L23: 2026년 4월 1일 | M23: 2027년 3월 31일 | N23: =L23&" ~ "&M23 -> 2026년 4월 1일 ~ 2027년 3월 31일 | O23: =VLOOKUP(B23,'25년계약체결리스트'!$B:$O,14,0) -> auk0903@naver.com
B24: 울산5 | C24: =VLOOKUP(B24,'2603실제'!$D:$E,2,0) -> 일반BS | D24: 현금 | E24: 이천만원 | F24: 20,000,000원 | G24: =E24&" (\"&F24&")" -> 이천만원 (\20,000,000원) | H24: 일룸 울산점 | I24: 301-45-04477 | J24: 조 정 혁 | K24: 울산광역시 남구 삼산로 361(삼산동) | L24: 2026년 4월 1일 | M24: 2027년 3월 31일 | N24: =L24&" ~ "&M24 -> 2026년 4월 1일 ~ 2027년 3월 31일 | O24: =VLOOKUP("울산4",'25년계약체결리스트'!$B:$O,14,0) -> gorgeouc@naver.com
B25: 원주3 | C25: =VLOOKUP(B25,'2603실제'!$D:$E,2,0) -> 일반BS | D25: 현금 | E25: 이천만원 | F25: 20,000,000원 | G25: =E25&" (\"&F25&")" -> 이천만원 (\20,000,000원) | H25: =VLOOKUP(B25,'25년계약체결리스트'!$B:$K,7,0) -> 일룸원주점 | I25: =VLOOKUP(B25,'25년계약체결리스트'!$B:$O,8,0) -> 224-07-71963 | J25: =VLOOKUP(B25,'25년계약체결리스트'!$B:$O,9,0) -> 이 정 복 | K25: =VLOOKUP(B25,'25년계약체결리스트'!$B:$O,10,0) -> 강원 원주시 호저면 원문로 668-9 만종가구단지 2층 | L25: 2026년 4월 1일 | M25: 2027년 3월 31일 | N25: =L25&" ~ "&M25 -> 2026년 4월 1일 ~ 2027년 3월 31일 | O25: =VLOOKUP(B25,'25년계약체결리스트'!$B:$O,14,0) -> jungbok35@hanmail.net
B26: 의정부8 | C26: =VLOOKUP(B26,'2603실제'!$D:$E,2,0) -> 일반BS | D26: 현금 | E26: 이천만원 | F26: 20,000,000원 | G26: =E26&" (\"&F26&")" -> 이천만원 (\20,000,000원) | H26: =VLOOKUP(B26,'25년계약체결리스트'!$B:$K,7,0) -> 일룸의정부브랜드샵 | I26: =VLOOKUP(B26,'25년계약체결리스트'!$B:$O,8,0) -> 550-88-00221 | J26: =VLOOKUP(B26,'25년계약체결리스트'!$B:$O,9,0) -> 이 경 숙 | K26: =VLOOKUP(B26,'25년계약체결리스트'!$B:$O,10,0) -> 경기 의정부시 민락로 397 | L26: 2026년 4월 1일 | M26: 2027년 3월 31일 | N26: =L26&" ~ "&M26 -> 2026년 4월 1일 ~ 2027년 3월 31일 | O26: =VLOOKUP(B26,'25년계약체결리스트'!$B:$O,14,0) -> jail5775@hanmail.net
B27: 인천중앙2 | C27: =VLOOKUP(B27,'2603실제'!$D:$E,2,0) -> 일반BS | D27: 현금 | E27: 이천만원 | F27: 20,000,000원 | G27: =E27&" (\"&F27&")" -> 이천만원 (\20,000,000원) | H27: =VLOOKUP(B27,'25년계약체결리스트'!$B:$K,7,0) -> (주)알루컴 인천점 | I27: =VLOOKUP(B27,'25년계약체결리스트'!$B:$O,8,0) -> 105-85-41701 | J27: =VLOOKUP(B27,'25년계약체결리스트'!$B:$O,9,0) -> 이 종 균 | K27: =VLOOKUP(B27,'25년계약체결리스트'!$B:$O,10,0) -> 인천 남동구 인주대로 644 | L27: 2026년 4월 1일 | M27: 2027년 3월 31일 | N27: =L27&" ~ "&M27 -> 2026년 4월 1일 ~ 2027년 3월 31일 | O27: =VLOOKUP(B27,'25년계약체결리스트'!$B:$O,14,0) -> uggugg@nate.com
B28: 일산킨텍스 | C28: =VLOOKUP(B28,'2603실제'!$D:$E,2,0) -> 일반BS | D28: 현금 | E28: 이천만원 | F28: 20,000,000원 | G28: =E28&" (\"&F28&")" -> 이천만원 (\20,000,000원) | H28: =VLOOKUP(B28,'25년계약체결리스트'!$B:$K,7,0) -> (주)플랜 디 | I28: =VLOOKUP(B28,'25년계약체결리스트'!$B:$O,8,0) -> 670-81-01506 | J28: =VLOOKUP(B28,'25년계약체결리스트'!$B:$O,9,0) -> 김정은, 안중협 | K28: =VLOOKUP(B28,'25년계약체결리스트'!$B:$O,10,0) -> 경기도 고양시 일산서구 탄중로 120, 1~2동(덕이동) | L28: 2026년 4월 1일 | M28: 2027년 3월 31일 | N28: =L28&" ~ "&M28 -> 2026년 4월 1일 ~ 2027년 3월 31일 | O28: =VLOOKUP(B28,'25년계약체결리스트'!$B:$O,14,0) -> garnet212@naver.com
B29: 전군2 | C29: =VLOOKUP(B29,'2603실제'!$D:$E,2,0) -> 일반BS | D29: 현금 | E29: 이천만원 | F29: 20,000,000원 | G29: =E29&" (\"&F29&")" -> 이천만원 (\20,000,000원) | H29: =VLOOKUP(B29,'25년계약체결리스트'!$B:$K,7,0) -> 일룸전군점 | I29: =VLOOKUP(B29,'25년계약체결리스트'!$B:$O,8,0) -> 403-03-30193 | J29: =VLOOKUP(B29,'25년계약체결리스트'!$B:$O,9,0) -> 안 상 준 | K29: =VLOOKUP(B29,'25년계약체결리스트'!$B:$O,10,0) -> 전북 김제시 백구면 영상3길 28-26 | L29: 2026년 4월 1일 | M29: 2027년 3월 31일 | N29: =L29&" ~ "&M29 -> 2026년 4월 1일 ~ 2027년 3월 31일 | O29: =VLOOKUP(B29,'25년계약체결리스트'!$B:$O,14,0) -> iloom4200@naver.com
B30: 중화산4 | C30: =VLOOKUP(B30,'2603실제'!$D:$E,2,0) -> 일반BS | D30: 현금 | E30: 이천만원 | F30: 20,000,000원 | G30: =E30&" (\"&F30&")" -> 이천만원 (\20,000,000원) | H30: =VLOOKUP(B30,'25년계약체결리스트'!$B:$K,7,0) -> 일룸중화산점 | I30: =VLOOKUP(B30,'25년계약체결리스트'!$B:$O,8,0) -> 402-20-78721 | J30: =VLOOKUP(B30,'25년계약체결리스트'!$B:$O,9,0) -> 양 유 진 | K30: =VLOOKUP(B30,'25년계약체결리스트'!$B:$O,10,0) -> 전북 전주시 완산구 중화산동2가 528-6 | L30: 2026년 4월 1일 | M30: 2027년 3월 31일 | N30: =L30&" ~ "&M30 -> 2026년 4월 1일 ~ 2027년 3월 31일 | O30: =VLOOKUP(B30,'25년계약체결리스트'!$B:$O,14,0) -> power5550@hanmail.net
B31: 진주2 | C31: =VLOOKUP(B31,'2603실제'!$D:$E,2,0) -> 일반BS | D31: 현금 | E31: 이천만원 | F31: 20,000,000원 | G31: =E31&" (\"&F31&")" -> 이천만원 (\20,000,000원) | H31: =VLOOKUP(B31,'25년계약체결리스트'!$B:$K,7,0) -> 일룸진주점 | I31: =VLOOKUP(B31,'25년계약체결리스트'!$B:$O,8,0) -> 613-06-76176 | J31: =VLOOKUP(B31,'25년계약체결리스트'!$B:$O,9,0) -> 김지융, 김현실 | K31: =VLOOKUP(B31,'25년계약체결리스트'!$B:$O,10,0) -> 경남 진주시 진주대로 638(가좌동) | L31: 2026년 4월 1일 | M31: 2027년 3월 31일 | N31: =L31&" ~ "&M31 -> 2026년 4월 1일 ~ 2027년 3월 31일 | O31: =VLOOKUP(B31,'25년계약체결리스트'!$B:$O,14,0) -> rlduql_par@naver.com
B32: 창원3 | C32: =VLOOKUP(B32,'2603실제'!$D:$E,2,0) -> 일반BS | D32: 현금 | E32: 이천만원 | F32: 20,000,000원 | G32: =E32&" (\"&F32&")" -> 이천만원 (\20,000,000원) | H32: =VLOOKUP(B32,'25년계약체결리스트'!$B:$K,7,0) -> (주)창원퍼시스 | I32: =VLOOKUP(B32,'25년계약체결리스트'!$B:$O,8,0) -> 609-81-43386 | J32: =VLOOKUP(B32,'25년계약체결리스트'!$B:$O,9,0) -> 정 진 환 | K32: =VLOOKUP(B32,'25년계약체결리스트'!$B:$O,10,0) -> 경상남도 창원시 의창구 창원대로 360 | L32: 2026년 4월 1일 | M32: 2027년 3월 31일 | N32: =L32&" ~ "&M32 -> 2026년 4월 1일 ~ 2027년 3월 31일 | O32: =VLOOKUP(B32,'25년계약체결리스트'!$B:$O,14,0) -> su2774@nate.com
B33: 청남3 | C33: =VLOOKUP(B33,'2603실제'!$D:$E,2,0) -> 일반BS | D33: 현금 | E33: 이천만원 | F33: 20,000,000원 | G33: =E33&" (\"&F33&")" -> 이천만원 (\20,000,000원) | H33: =VLOOKUP(B33,'25년계약체결리스트'!$B:$K,7,0) -> 일룸청남점 | I33: =VLOOKUP(B33,'25년계약체결리스트'!$B:$O,8,0) -> 745-10-00252 | J33: =VLOOKUP(B33,'25년계약체결리스트'!$B:$O,9,0) -> 박 종 상 | K33: =VLOOKUP(B33,'25년계약체결리스트'!$B:$O,10,0) -> 충북 청주시 서원구 남이면 가구단지길 21-3 청남가구단지 105호 | L33: 2026년 4월 1일 | M33: 2027년 3월 31일 | N33: =L33&" ~ "&M33 -> 2026년 4월 1일 ~ 2027년 3월 31일 | O33: =VLOOKUP(B33,'25년계약체결리스트'!$B:$O,14,0) -> brqok@naver.com
B34: 청주6 | C34: =VLOOKUP(B34,'2603실제'!$D:$E,2,0) -> 일반BS | D34: 현금 | E34: 이천만원 | F34: 20,000,000원 | G34: =E34&" (\"&F34&")" -> 이천만원 (\20,000,000원) | H34: =VLOOKUP(B34,'25년계약체결리스트'!$B:$K,7,0) -> (주)조은파트너스 | I34: =VLOOKUP(B34,'25년계약체결리스트'!$B:$O,8,0) -> 335-87-02787 | J34: =VLOOKUP(B34,'25년계약체결리스트'!$B:$O,9,0) -> 최 현 수 | K34: =VLOOKUP(B34,'25년계약체결리스트'!$B:$O,10,0) -> 충북 청주시 상당구 용암동 1587 | L34: 2026년 4월 1일 | M34: 2027년 3월 31일 | N34: =L34&" ~ "&M34 -> 2026년 4월 1일 ~ 2027년 3월 31일 | O34: =VLOOKUP(B34,'25년계약체결리스트'!$B:$O,14,0) -> iloom_cj@naver.com
B35: 청주중앙4 | C35: =VLOOKUP(B35,'2603실제'!$D:$E,2,0) -> 일반BS | D35: 현금 | E35: 이천만원 | F35: 20,000,000원 | G35: =E35&" (\"&F35&")" -> 이천만원 (\20,000,000원) | H35: =VLOOKUP(B35,'25년계약체결리스트'!$B:$K,7,0) -> (주)일룸청주중앙점 | I35: =VLOOKUP(B35,'25년계약체결리스트'!$B:$O,8,0) -> 785-86-00352 | J35: =VLOOKUP(B35,'25년계약체결리스트'!$B:$O,9,0) -> 함 지 연 | K35: =VLOOKUP(B35,'25년계약체결리스트'!$B:$O,10,0) -> 충북 청주시 흥덕구 강서로 55, 2층 | L35: 2026년 4월 1일 | M35: 2027년 3월 31일 | N35: =L35&" ~ "&M35 -> 2026년 4월 1일 ~ 2027년 3월 31일 | O35: =VLOOKUP(B35,'25년계약체결리스트'!$B:$O,14,0) -> iloom1@nate.com
B36: 춘천3 | C36: =VLOOKUP(B36,'2603실제'!$D:$E,2,0) -> 일반BS | D36: 현금 | E36: 이천만원 | F36: 20,000,000원 | G36: =E36&" (\"&F36&")" -> 이천만원 (\20,000,000원) | H36: =VLOOKUP(B36,'25년계약체결리스트'!$B:$K,7,0) -> 퍼시스춘천전시장 | I36: =VLOOKUP(B36,'25년계약체결리스트'!$B:$O,8,0) -> 221-02-56686 | J36: =VLOOKUP(B36,'25년계약체결리스트'!$B:$O,9,0) -> 이 신 구 | K36: =VLOOKUP(B36,'25년계약체결리스트'!$B:$O,10,0) -> 강원 춘천시 동면 만천리 700번지 | L36: 2026년 4월 1일 | M36: 2027년 3월 31일 | N36: =L36&" ~ "&M36 -> 2026년 4월 1일 ~ 2027년 3월 31일 | O36: =VLOOKUP(B36,'25년계약체결리스트'!$B:$O,14,0) -> 2625577@gmail.com
B37: 평택5 | C37: =VLOOKUP(B37,'2603실제'!$D:$E,2,0) -> 일반BS | D37: 현금 | E37: 이천만원 | F37: 20,000,000원 | G37: =E37&" (\"&F37&")" -> 이천만원 (\20,000,000원) | H37: 와이더블유 퍼니처 | I37: 287-03-03982 | J37: 오 용 택 | K37: 경기도 안성시 공도읍 서동대로 3924 | L37: 2026년 4월 1일 | M37: 2027년 3월 31일 | N37: =L37&" ~ "&M37 -> 2026년 4월 1일 ~ 2027년 3월 31일 | O37: =VLOOKUP(B37,'25년계약체결리스트'!$B:$O,14,0) -> #N/A
B38: 포항중앙2 | C38: =VLOOKUP(B38,'2603실제'!$D:$E,2,0) -> 일반BS | D38: 현금 | E38: 이천만원 | F38: 20,000,000원 | G38: =E38&" (\"&F38&")" -> 이천만원 (\20,000,000원) | H38: =VLOOKUP(B38,'25년계약체결리스트'!$B:$K,7,0) -> 일룸포항중앙점 | I38: =VLOOKUP(B38,'25년계약체결리스트'!$B:$O,8,0) -> 506-14-15162 | J38: =VLOOKUP(B38,'25년계약체결리스트'!$B:$O,9,0) -> 신 현 정 | K38: =VLOOKUP(B38,'25년계약체결리스트'!$B:$O,10,0) -> 경북 포항시 북구 중흥로213번길 49 | L38: 2026년 4월 1일 | M38: 2027년 3월 31일 | N38: =L38&" ~ "&M38 -> 2026년 4월 1일 ~ 2027년 3월 31일 | O38: =VLOOKUP(B38,'25년계약체결리스트'!$B:$O,14,0) -> shjj_2000@hanmail.net
B39: 하단3 | C39: =VLOOKUP(B39,'2603실제'!$D:$E,2,0) -> 일반BS | D39: 현금 | E39: 이천만원 | F39: 20,000,000원 | G39: =E39&" (\"&F39&")" -> 이천만원 (\20,000,000원) | H39: =VLOOKUP(B39,'25년계약체결리스트'!$B:$K,7,0) -> 일룸부산하단점 | I39: =VLOOKUP(B39,'25년계약체결리스트'!$B:$O,8,0) -> 617-29-91066 | J39: =VLOOKUP(B39,'25년계약체결리스트'!$B:$O,9,0) -> 우 영 숙 | K39: =VLOOKUP(B39,'25년계약체결리스트'!$B:$O,10,0) -> 부산광역시 사하구 낙동남로 1359 (하단동) | L39: 2026년 4월 1일 | M39: 2027년 3월 31일 | N39: =L39&" ~ "&M39 -> 2026년 4월 1일 ~ 2027년 3월 31일 | O39: =VLOOKUP(B39,'25년계약체결리스트'!$B:$O,14,0) -> iloom0710@naver.com
B40: NC대전유성 | C40: =VLOOKUP(B40,'2603실제'!$D:$E,2,0) -> 입점BS | D40: 현금 | E40: 이천만원 | F40: 20,000,000원 | G40: =E40&" (\"&F40&")" -> 이천만원 (\20,000,000원) | H40: =VLOOKUP("신세계대전",'25년계약체결리스트'!$B:$K,7,0) -> 일룸 NC대전유성점 | I40: =VLOOKUP("신세계대전",'25년계약체결리스트'!$B:$O,8,0) -> 314-27-63783 | J40: =VLOOKUP("신세계대전",'25년계약체결리스트'!$B:$O,9,0) -> 류 대 열 | K40: 대전광역시 유성구 계룡로 119, 7층(봉명동) | L40: 2026년 4월 1일 | M40: 2027년 3월 31일 | N40: =L40&" ~ "&M40 -> 2026년 4월 1일 ~ 2027년 3월 31일 | O40: =VLOOKUP("신세계대전",'25년계약체결리스트'!$B:$O,14,0) -> kianadol76@daum.net
B41: 롯데광복2 | C41: =VLOOKUP(B41,'2603실제'!$D:$E,2,0) -> 입점BS | D41: 현금 | E41: 이천만원 | F41: 20,000,000원 | G41: =E41&" (\"&F41&")" -> 이천만원 (\20,000,000원) | H41: =VLOOKUP(B41,'25년계약체결리스트'!$B:$K,7,0) -> 일룸 롯데광복점 | I41: =VLOOKUP(B41,'25년계약체결리스트'!$B:$O,8,0) -> 173-62-00679 | J41: =VLOOKUP(B41,'25년계약체결리스트'!$B:$O,9,0) -> 조 정 혁 | K41: =VLOOKUP(B41,'25년계약체결리스트'!$B:$O,10,0) -> 부산광역시 중구 중앙대로 2, 8층 | L41: 2026년 4월 1일 | M41: 2026년 7월 31일 | N41: =L41&" ~ "&M41 -> 2026년 4월 1일 ~ 2026년 7월 31일 | O41: =VLOOKUP(B41,'25년계약체결리스트'!$B:$O,14,0) -> iloomgo@naver.com
...

Sheet 대리점유통망2603
B2: 담당자 | C2: 사업소 | D2: 대리점 | E2: 유형 | F2: 평수 (계약면적) | G2: TEL | H2: 매장코드 | I2: 주소 | J2: 대표
B3: 최지연 | C3: 대구 | D3: 경주4 | E3: S | F3: 120 | G3: 054-744-1117 | H3: 61LM70 | I3: 경상북도 경주시 원화로468 | J3: 신도철
D4: 구미5 | E4: B | F4: 255 | G4: 054-454-6456 | H4: 61LM71 | I4: 경상북도 구미시 산업로28길 4 | J4: 김동윤
D5: 달서5 | E5: B | F5: 300 | G5: 053-623-8924 | H5: 61LM07 | I5: 대구광역시 달서구 조암로 200 2층~4층 | J5: 서미경
D6: 수성5 | E6: B | F6: 352 | G6: 053-753-6060 | H6: 61LM75 | I6: 대구광역시 수성구 희망로 152 | J6: 조진희
D7: 안동5 | E7: S | F7: 144 | G7: 054-858-4332 | H7: 61LM76 | I7: 경상북도 안동시 하이마로 151 | J7: 조현주
D8: 포항2 | E8: S | F8: 100 | G8: 054-249-1358 | H8: 61LM80 | I8: 경상북도 포항시 북구 환호로 75 | J8: 홍정기
D9: 포항중앙2 | E9: B | F9: 172 | G9: 054-274-6400 | H9: 61LM81 | I9: 경상북도 포항시 북구 중흥로213번길 49 | J9: 신현정
C10: 경기 | D10: 스타필드고양 | E10: 투자형B | F10: 520 | G10: 02-6951-2528 | H10: 173075 | I10: 경기도 고양시 덕양구 고양대로 1955 스타필드고양 지하1층 | J10: 안중우
D11: 신세계파주2 | E11: 투자형B | F11: 143 | G11: 031-8071-7475 | H11: 62LM01 | I11: 경기도 파주시 탄현면 필승로 200, 신세계파주 프리미엄 아울렛 3층 | J11: 김정은
D12: 일산킨텍스 | E12: B | F12: 350 | G12: 031-903-0233 | H12: 62LM08 | I12: 경기도 고양시 일산동구 월드고양로 102-33 | J12: 김정은
B13: 채선경 | C13: 경기 | D13: 롯데광명 | E13: 투자형B | F13: 195 | G13: 02-6226-2490 | H13: 61LM90 | I13: 경기도 광명시 일직로 17, 롯데프리미엄아울렛 광명점 4층 | J13: 박철홍
D14: 안산상록수2 | E14: S | F14: 77 | G14: 031-501-2199 | H14: 61LM25 | I14: 경기도 안산시 상록구 용신로 451-1 | J14: 장정윤
D15: 안양 | E15: 투자형B | F15: 360 | G15: 031-468-9600 | H15: 62LM04 | I15: 경기도 안양시 만안구 안양로 238 | J15: 윤기언
D16: 기흥4 | E16: 투자형B | F16: 262 | G16: 031-281-3202 | H16: 61LM86 | I16: 경기도 용인시 기흥구 신고매로 59 리빙파워센터 B2 | J16: 이명수
D17: 롯데동탄2 | E17: 입점BS | F17: 30 | G17: 031-8036-3634 | H17: 215500 | I17: 경기도 화성시 동탄역로 160 롯데백화점 동탄점 4층 | J17: 박철홍
D18: 롯데평촌 | E18: 투자형B | F18: 48 | G18: 031-8086-9624 | H18: 62LM17 | I18: 경기도 안양시 동안구 시민대로 180, 롯데백화점 6층 | J18: 황봉국
D19: 롯데의왕 | E19: 입점BS | F19: 8.3 | G19: 031-329-4059 | H19: IL0009 | I19: 경기도 의왕시 바라산로 1(학의동) 롯데프리미엄아울렛 의왕점 | J19: 황봉국
D20: 분당2 | E20: B | F20: 215 | G20: 031-726-7003 | H20: 61LM17 | I20: 경기도 성남시 분당구 대왕판교로214 | J20: 최상헌
D21: 평택5 | E21: B | F21: 280 | G21: 031-656-8666 | H21: IL0015 | I21: 경기도 안성시 공도읍 진사리 10-3 | J21: 오용택
D22: 스타필드수원(6층) | E22: 투자형B | F22: 208 | G22: 031-690-1630 | H22: 237664 | I22: 경기도 수원시 장안구 수성로 175 (정자동), 스타필드수원 6층 | J22: 석옥련
D23: 스타필드수원키즈(3층) | E23: 투자형B | F23: 45 | G23: 031-690-1352 | H23: 237665 | I23: 경기도 수원시 장안구 수성로 175 (정자동), 스타필드수원키즈 3층 | J23: 석옥련
D24: 롯데수지 | E24: 입점BS | F24: 92.1 | G24: 010-4255-6255 | H24: IL0019 | I24: 경기도 용인시 수지구 성복2로 38 롯데몰 수지점 3층 | J24: 이상훈
D25: 롯데안산(팝업) | E25: 입점BS | F25: 16.5 | G25: 010-5625-1902 | H25: 62LM30 | I25: 경기도 안산시 단원구 고잔1길 12 롯데백화점안산점 신관 3층 | J25: 최하은
B26: 김지수 | C26: 서울 | D26: 롯데청량리 | E26: 입점BS | F26: 24 | G26: 02-3707-1621 | H26: 62LM15 | I26: 서울특별시 동대문구 왕산로 214, 롯데백화점 청량리점 6층 | J26: 오중현
D27: 롯데미아 | E27: 입점BS | F27: 39 | G27: 02-944-2871 | H27: 62LM34 | I27: 서울특별시 강북구 도봉로 62 롯데백화점미아점 8층 | J27: 오중현
C28: 대전 | D28: 대전도안3 | E28: 투자형B | F28: 279 | G28: 042-542-1625 | H28: 61LM14 | I28: 대전광역시 서구 가수원동 1061 리더스프라자 B동 2~3층 | J28: 류대열
D29: 서대전3 | E29: S | F29: 183 | G29: 042-223-3800 | H29: 61LM51 | I29: 대전광역시 중구 중앙로 8, 가구갤러리 6층 | J29: 김영애
D30: 서산4 | E30: S | F30: 106 | G30: 041-668-4006 | H30: 62LM60 | I30: 충청남도 서산시 서해로 3449 | J30: 김정남
D31: 세종2 | E31: B | F31: 260 | G31: 044-863-9939 | H31: 61LM53 | I31: 세종특별자치시 세종로 1232 정원타워 3층, 4층 | J31: 박정나
D32: 천안신방3 | E32: 투자형B | F32: 296 | G32: 041-575-8985 | H32: 61LM55 | I32: 충청남도 천안시 동남구 신방동 787-5 | J32: 이준범
D33: 천안불당3 | E33: B | F33: 241 | G33: 041-577-4585 | H33: 61LM54 | I33: 충청남도 천안시 불당동 719번지 | J33: 김은미
D34: 청남3 | E34: S | F34: 165 | G34: 043-269-3534 | H34: 61LM56 | I34: 충청북도 청주시 서원구 남이면 가구단지길 21-3 청남가구단지 105호 | J34: 박종상
D35: 청주6 | E35: B | F35: 295 | G35: 043-267-1616 | H35: 61LM57 | I35: 충청북도 청주시 상당구 용암동 1587 | J35: 최현수
D36: 청주중앙4 | E36: S | F36: 120 | G36: 043-231-3881 | H36: 61LM58 | I36: 충청북도 청주시 흥덕구 강서동 123-5 2층 | J36: 함지연
D37: 신세계대전(팝업) | E37: 투자형B | F37: 11 | G37: 010-4206-3476 | H37: 62LM14 | I37: 대전광역시 유성구 엑스포로 1 (도룡동) 신세계백화점 대전점 7층 | J37: 류대열
D38: NC대전유성 | E38: 입점BS | F38: 143 | G38: 042-332-0385 | H38: IL0003 | I38: 대전광역시 유성구 계룡로 119(봉명동) 7층 | J38: 류대열
B39: 조아라 | C39: 광주 | D39: 광천5 | E39: 투자형B | F39: 396 | G39: 062-361-8761 | H39: 61LM15 | I39: 광주광역시 서구 무진대로 956, 퍼시스 광주센터 1층, 2층 | J39: 조평호
D40: 덕진2 | E40: B | F40: 300 | G40: 063-252-1616 | H40: 61LM60 | I40: 전라북도 전주시 덕진구 송천중앙로 6 | J40: 유수정
D41: 봉선5 | E41: B | F41: 350 | G41: 062-651-7733 | H41: 61LM62 | I41: 광주광역시 남구 봉선로 16 | J41: 조평호
...

Sheet 2603실제
B2: 담당 | C2: 지역 | D2: 대리점 | E2: 구분 | F2: 계약기간 | G2: 임차구분
B3: 조아라 | C3: 광주 | D3: 광천5 | E3: 투자형B-로드 | F3: 46387 | G3: 46387
B4: 조아라 | C4: 대구 | D4: 강릉4 | E4: 일반BS
B5: 이광호 | C5: 부산 | D5: 롯데광복2 | E5: 입점BS | F5: 46234 | G5: 46234
B6: 서다솔 | C6: 경기 | D6: 롯데구리 | E6: 입점BS | F6: 46418 | G6: 46418
B7: 이광호 | C7: 부산 | D7: 롯데동부산2 | E7: 투자형B-입점 | F7: 46203 | G7: 46203
B8: 채선경 | C8: 경기 | D8: 롯데동탄2 | E8: 입점BS | F8: 46418 | G8: 46418
B9: 김지수 | C9: 서울 | D9: 롯데미아 | E9: 입점BS | F9: 46418 | G9: 46418
B10: 채선경 | C10: 경기 | D10: 롯데수지 | E10: 입점BS | F10: 46234 | G10: 46234
B11: 채선경 | C11: 경기 | D11: 롯데안산(팝업) | E11: 입점BS | F11: 46142 | G11: 46142
B12: 서다솔 | C12: 서울 | D12: 롯데영등포 | E12: 입점BS | F12: 46144 | G12: 46144
B13: 김지수 | C13: 대전 | D13: 대전도안3 | E13: 투자형B-로드
B14: 서다솔 | C14: 경기 | D14: 롯데인천 | E14: 입점BS | F14: 46173 | G14: 46173
B15: 김지수 | C15: 서울 | D15: 롯데청량리 | E15: 입점BS | F15: 46418 | G15: 46418
B16: 채선경 | C16: 경기 | D16: 롯데평촌 | E16: 투자형B-입점 | F16: 46418 | G16: 46418
B17: 서다솔 | C17: 경기 | D17: 부천3 | E17: 일반BS | F17: 46387 | G17: 46387
B18: 서다솔 | C18: 경기 | D18: 송도5 | E18: 투자형B-입점 | F18: 46265 | G18: 46265
B19: 채선경 | C19: 경기 | D19: 스타필드수원키즈(3층) | E19: 투자형B-입점 | F19: 46412 | G19: 46412
B20: 조아라 | C20: 광주 | D20: 롯데몰여수(팝업) | E20: 입점BS
B21: 김지수 | C21: 대전 | D21: 신세계대전(팝업) | E21: 입점BS | F21: 46234 | G21: 46234
B22: 최지연 | C22: 경기 | D22: 신세계파주2 | E22: 투자형B-입점 | F22: 46152 | G22: 46152
B23: 서다솔 | C23: 경기 | D23: 현대중동 | E23: 입점BS | F23: 46135 | G23: 46135
B24: 김지수 | C24: 대전 | D24: NC대전유성 | E24: 입점BS | F24: 46477 | G24: 46996
B25: 채선경 | C25: 경기 | D25: 롯데의왕 | E25: 입점BS
B26: 이광호 | C26: 부산 | D26: 거제4 | E26: 일반BS | F26: 46477
B27: 최지연 | C27: 대구 | D27: 경주4 | E27: 일반BS | F27: 46477
B28: 최지연 | C28: 대구 | D28: 구미5 | E28: 일반BS | F28: 46477
B29: 채선경 | C29: 경기 | D29: 기흥4 | E29: 투자형B-입점 | F29: 46477 | G29: 46506
B30: 서다솔 | C30: 경기 | D30: 김포5 | E30: 일반BS | F30: 46477
B31: 이광호 | C31: 부산 | D31: 김해2 | E31: 일반BS | F31: 46477
B32: 최지연 | C32: 대구 | D32: 달서5 | E32: 일반BS | F32: 46477
B33: 조아라 | C33: 광주 | D33: 덕진2 | E33: 일반BS | F33: 46477
B34: 채선경 | C34: 경기 | D34: 롯데광명 | E34: 투자형B-입점 | F34: 46477 | G34: 46591
B35: 이광호 | C35: 부산 | D35: 마산6 | E35: 일반BS | F35: 46477
B36: 조아라 | C36: 광주 | D36: 봉선5 | E36: 일반BS | F36: 46477
B37: 채선경 | C37: 경기 | D37: 분당2 | E37: 일반BS | F37: 46477
B38: 조아라 | C38: 광주 | D38: 빛고을3 | E38: 일반BS | F38: 46477
B39: 김지수 | C39: 대전 | D39: 서대전3 | E39: 일반BS | F39: 46477
B40: 김지수 | C40: 대전 | D40: 서산4 | E40: 일반BS | F40: 46477
B41: 김지수 | C41: 대전 | D41: 세종2 | E41: 일반BS | F41: 46477
...

Sheet 25년계약체결리스트
B2: 대리점명 | C2: 대리점유형 | D2: 25년 거래보증금 설정 | G2: 24거래보증금 | H2: 사업자명 | I2: 사업자번호 | J2: 대표 | K2: 주소 | L2: 계약시작 | M2: 계약만료 | N2: 계약기간 | O2: 메일
B3: 강릉4 | C3: =VLOOKUP(B3,'2503기준유통망'!$B:$F,5,0) -> B/S-Shop | D3: 현금 | E3: 이천만원 | F3: 20,000,000원 | G3: =E3&" (\"&F3&")" -> 이천만원 (\20,000,000원) | H3: =VLOOKUP(B3,계약체결용!$B:$K,7,0) -> 일룸강릉브랜드샵(주) | I3: =VLOOKUP(B3,계약체결용!$B:$K,8,0) -> 201-86-45638 | J3: =VLOOKUP(B3,계약체결용!$B:$K,9,0) -> 최 종 섭 | K3: =VLOOKUP(B3,계약체결용!$B:$K,10,0) -> 강원 강릉시 율곡로 3190 | L3: 2025년 4월 1일 | M3: 2026년 3월 31일 | N3: =L3&" ~ "&M3 -> 2025년 4월 1일 ~ 2026년 3월 31일 | O3: gniloom@daum.net
B4: 거제4 | C4: =VLOOKUP(B4,'2503기준유통망'!$B:$F,5,0) -> B/S-Shop | D4: 현금 | E4: 이천만원 | F4: 20,000,000원 | G4: =E4&" (\"&F4&")" -> 이천만원 (\20,000,000원) | H4: 일룸 거제점 | I4: 178-73-00699 | J4: 안 율 | K4: 경상남도 거제시 수양로 454-40, 2층(수월동) | L4: 2025년 4월 1일 | M4: 2026년 3월 31일 | N4: =L4&" ~ "&M4 -> 2025년 4월 1일 ~ 2026년 3월 31일 | O4: ld5yul@hanmail.net
B5: 경주4 | C5: =VLOOKUP(B5,'2503기준유통망'!$B:$F,5,0) -> B/S-Shop | D5: 현금 | E5: 이천만원 | F5: 20,000,000원 | G5: =E5&" (\"&F5&")" -> 이천만원 (\20,000,000원) | H5: =VLOOKUP(B5,계약체결용!$B:$K,7,0) -> 그린퍼니처 | I5: =VLOOKUP(B5,계약체결용!$B:$K,8,0) -> 505-09-65796 | J5: =VLOOKUP(B5,계약체결용!$B:$K,9,0) -> 신 도 철 | K5: =VLOOKUP(B5,계약체결용!$B:$K,10,0) -> 경북 경주시 원화로468, b동 | L5: 2025년 4월 1일 | M5: 2026년 3월 31일 | N5: =L5&" ~ "&M5 -> 2025년 4월 1일 ~ 2026년 3월 31일 | O5: ch9000@hanmail.net
B6: 구리남양주2 | C6: =VLOOKUP(B6,'2503기준유통망'!$B:$F,5,0) -> B/S-Shop | D6: 현금 | E6: 이천만원 | F6: 20,000,000원 | G6: =E6&" (\"&F6&")" -> 이천만원 (\20,000,000원) | H6: =VLOOKUP(B6,계약체결용!$B:$K,7,0) -> 일룸 구리남양주점 | I6: =VLOOKUP(B6,계약체결용!$B:$K,8,0) -> 228-27-00532 | J6: =VLOOKUP(B6,계약체결용!$B:$K,9,0) -> 박 상 근 | K6: =VLOOKUP(B6,계약체결용!$B:$K,10,0) -> 경기 구리시 경춘로 286, 2,3,4층 | L6: 2025년 4월 1일 | M6: 2025년 5월 31일 | N6: =L6&" ~ "&M6 -> 2025년 4월 1일 ~ 2025년 5월 31일 | O6: skparknv@naver.com
B7: 구미5 | C7: =VLOOKUP(B7,'2503기준유통망'!$B:$F,5,0) -> B/S-Shop | D7: 현금 | E7: 이천만원 | F7: 20,000,000원 | G7: =E7&" (\"&F7&")" -> 이천만원 (\20,000,000원) | H7: =VLOOKUP(B7,계약체결용!$B:$K,7,0) -> 일룸 가구 구미점 | I7: =VLOOKUP(B7,계약체결용!$B:$K,8,0) -> 283-05-01540 | J7: =VLOOKUP(B7,계약체결용!$B:$K,9,0) -> 김관우, 김동윤, 박정애 | K7: =VLOOKUP(B7,계약체결용!$B:$K,10,0) -> 경북 구미시 산업로28길 4 | L7: 2025년 4월 1일 | M7: 2026년 3월 31일 | N7: =L7&" ~ "&M7 -> 2025년 4월 1일 ~ 2026년 3월 31일 | O7: ktongyun@hanmail.net
B8: 김포5 | C8: =VLOOKUP(B8,'2503기준유통망'!$B:$F,5,0) -> B/S-Shop | D8: 현금 | E8: 이천만원 | F8: 20,000,000원 | G8: =E8&" (\"&F8&")" -> 이천만원 (\20,000,000원) | H8: =VLOOKUP(B8,계약체결용!$B:$K,7,0) -> 일룸김포점 | I8: =VLOOKUP(B8,계약체결용!$B:$K,8,0) -> 137-17-39033 | J8: =VLOOKUP(B8,계약체결용!$B:$K,9,0) -> 장 미 영 | K8: =VLOOKUP(B8,계약체결용!$B:$K,10,0) -> 경기 김포시 풍무동 27-4 1,2층 | L8: 2025년 4월 1일 | M8: 2026년 3월 31일 | N8: =L8&" ~ "&M8 -> 2025년 4월 1일 ~ 2026년 3월 31일 | O8: kanges232@naver.com
B9: 김해2 | C9: =VLOOKUP(B9,'2503기준유통망'!$B:$F,5,0) -> B/S-Shop | D9: 현금 | E9: 이천만원 | F9: 20,000,000원 | G9: =E9&" (\"&F9&")" -> 이천만원 (\20,000,000원) | H9: =VLOOKUP(B9,계약체결용!$B:$K,7,0) -> 일룸 김해브랜드샵 | I9: =VLOOKUP(B9,계약체결용!$B:$K,8,0) -> 615-17-27736 | J9: =VLOOKUP(B9,계약체결용!$B:$K,9,0) -> 박 효 정 | K9: =VLOOKUP(B9,계약체결용!$B:$K,10,0) -> 경남 김해시 풍유동 47-3 | L9: 2025년 4월 1일 | M9: 2026년 3월 31일 | N9: =L9&" ~ "&M9 -> 2025년 4월 1일 ~ 2026년 3월 31일 | O9: iloomju@naver.com
B10: 달서5 | C10: =VLOOKUP(B10,'2503기준유통망'!$B:$F,5,0) -> B/S-Shop | D10: 현금 | E10: 이천만원 | F10: 20,000,000원 | G10: =E10&" (\"&F10&")" -> 이천만원 (\20,000,000원) | H10: =VLOOKUP(B10,계약체결용!$B:$K,7,0) -> 일룸달서프리미엄샵 | I10: =VLOOKUP(B10,계약체결용!$B:$K,8,0) -> 514-19-58959 | J10: =VLOOKUP(B10,계약체결용!$B:$K,9,0) -> 서 미 경 | K10: =VLOOKUP(B10,계약체결용!$B:$K,10,0) -> 대구 달서구 조암로 200(유천동) | L10: 2025년 4월 1일 | M10: 2026년 3월 31일 | N10: =L10&" ~ "&M10 -> 2025년 4월 1일 ~ 2026년 3월 31일 | O10: heraseo219@nate.com
B11: 덕진2 | C11: =VLOOKUP(B11,'2503기준유통망'!$B:$F,5,0) -> B/S-Shop | D11: 현금 | E11: 이천만원 | F11: 20,000,000원 | G11: =E11&" (\"&F11&")" -> 이천만원 (\20,000,000원) | H11: =VLOOKUP(B11,계약체결용!$B:$K,7,0) -> 일룸 덕진점 | I11: =VLOOKUP(B11,계약체결용!$B:$K,8,0) -> 418-06-94448 | J11: =VLOOKUP(B11,계약체결용!$B:$K,9,0) -> 유 수 정 | K11: =VLOOKUP(B11,계약체결용!$B:$K,10,0) -> 전북 전주시 덕진구 송천중앙로 6 | L11: 2025년 4월 1일 | M11: 2026년 3월 31일 | N11: =L11&" ~ "&M11 -> 2025년 4월 1일 ~ 2026년 3월 31일 | O11: elioom@nate.com
B12: 마산6 | C12: =VLOOKUP(B12,'2503기준유통망'!$B:$F,5,0) -> B/S-Shop | D12: 현금 | E12: 이천만원 | F12: 20,000,000원 | G12: =E12&" (\"&F12&")" -> 이천만원 (\20,000,000원) | H12: =VLOOKUP(B12,계약체결용!$B:$K,7,0) -> 퍼시스스마트OPC(극동) | I12: =VLOOKUP(B12,계약체결용!$B:$K,8,0) -> 608-47-60393 | J12: =VLOOKUP(B12,계약체결용!$B:$K,9,0) -> 강 호 근 | K12: =VLOOKUP(B12,계약체결용!$B:$K,10,0) -> 경남 창원시 마산회원구 봉양로 187(봉암동) | L12: 2025년 4월 1일 | M12: 2026년 3월 31일 | N12: =L12&" ~ "&M12 -> 2025년 4월 1일 ~ 2026년 3월 31일 | O12: smartopc@naver.com
B13: 봉선5 | C13: =VLOOKUP(B13,'2503기준유통망'!$B:$F,5,0) -> B/S-Shop | D13: 현금 | E13: 이천만원 | F13: 20,000,000원 | G13: =E13&" (\"&F13&")" -> 이천만원 (\20,000,000원) | H13: =VLOOKUP(B13,계약체결용!$B:$K,7,0) -> 주식회사 일룸앤데스커 | I13: =VLOOKUP(B13,계약체결용!$B:$K,8,0) -> 408-88-02821 | J13: =VLOOKUP(B13,계약체결용!$B:$K,9,0) -> 조 평 호 | K13: =VLOOKUP(B13,계약체결용!$B:$K,10,0) -> 광주광역시 남구 봉선로 16 (주월동) 1층 | L13: 2025년 4월 1일 | M13: 2026년 3월 31일 | N13: =L13&" ~ "&M13 -> 2025년 4월 1일 ~ 2026년 3월 31일 | O13: gagu0512@naver.com
B14: 부천3 | C14: =VLOOKUP(B14,'2503기준유통망'!$B:$F,5,0) -> B/S-Shop | D14: 현금 | E14: 이천만원 | F14: 20,000,000원 | G14: =E14&" (\"&F14&")" -> 이천만원 (\20,000,000원) | H14: =VLOOKUP(B14,계약체결용!$B:$K,7,0) -> 일룸 부천점 | I14: =VLOOKUP(B14,계약체결용!$B:$K,8,0) -> 313-36-00088 | J14: =VLOOKUP(B14,계약체결용!$B:$K,9,0) -> 최 민 영 | K14: =VLOOKUP(B14,계약체결용!$B:$K,10,0) -> 경기 부천시 길주로 462 | L14: 2026년 1월 1일 | M14: 2026년 3월 31일 | N14: =L14&" ~ "&M14 -> 2026년 1월 1일 ~ 2026년 3월 31일 | O14: iloombc@naver.com
B15: 분당2 | C15: =VLOOKUP(B15,'2503기준유통망'!$B:$F,5,0) -> B/S-Shop | D15: 현금 | E15: 이천만원 | F15: 20,000,000원 | G15: =E15&" (\"&F15&")" -> 이천만원 (\20,000,000원) | H15: =VLOOKUP(B15,계약체결용!$B:$K,7,0) -> 일룸분당점 | I15: =VLOOKUP(B15,계약체결용!$B:$K,8,0) -> 135-10-97912 | J15: =VLOOKUP(B15,계약체결용!$B:$K,9,0) -> 최 상 헌 | K15: =VLOOKUP(B15,계약체결용!$B:$K,10,0) -> 경기도 성남시 분당구 대왕판교로214 | L15: 2025년 4월 1일 | M15: 2026년 3월 31일 | N15: =L15&" ~ "&M15 -> 2025년 4월 1일 ~ 2026년 3월 31일 | O15: csh6797@naver.com
B16: 빛고을2 | C16: =VLOOKUP(B16,'2503기준유통망'!$B:$F,5,0) -> B/S-Shop | D16: 현금 | E16: 이천만원 | F16: 20,000,000원 | G16: =E16&" (\"&F16&")" -> 이천만원 (\20,000,000원) | H16: =VLOOKUP(B16,계약체결용!$B:$K,7,0) -> 일룸굿모닝엠에스(주) | I16: =VLOOKUP(B16,계약체결용!$B:$K,8,0) -> 410-86-88925 | J16: =VLOOKUP(B16,계약체결용!$B:$K,9,0) -> 최 정 우 | K16: =VLOOKUP(B16,계약체결용!$B:$K,10,0) -> 광주 광산구 하남대로 352 3층 일룸빛고을점 | L16: 2025년 4월 1일 | M16: 2026년 3월 31일 | N16: =L16&" ~ "&M16 -> 2025년 4월 1일 ~ 2026년 3월 31일 | O16: woowby@naver.com
B17: 빛고을3 | C17: B/S-Shop | D17: 현금 | E17: 이천만원 | F17: 20,000,000원 | G17: =E17&" (\"&F17&")" -> 이천만원 (\20,000,000원) | H17: 일룸빛고을점 | I17: 415-48-01330 | J17: 최 정 우 | K17: 광주광역시 광산구 하남대로 352, 3층(신가동) | L17: 2025년 5월 29일 | M17: 2026년 3월 31일 | N17: =L17&" ~ "&M17 -> 2025년 5월 29일 ~ 2026년 3월 31일 | O17: woowby@naver.com
B18: 서대전3 | C18: =VLOOKUP(B18,'2503기준유통망'!$B:$F,5,0) -> B/S-Shop | D18: 현금 | E18: 이천만원 | F18: 20,000,000원 | G18: =E18&" (\"&F18&")" -> 이천만원 (\20,000,000원) | H18: =VLOOKUP(B18,계약체결용!$B:$K,7,0) -> 일룸서대전점2 | I18: =VLOOKUP(B18,계약체결용!$B:$K,8,0) -> 305-29-60452 | J18: =VLOOKUP(B18,계약체결용!$B:$K,9,0) -> 김 영 애 | K18: =VLOOKUP(B18,계약체결용!$B:$K,10,0) -> 대전 중구 중앙로 8 (문화동, 가구갤러리 8층) | L18: 2025년 4월 1일 | M18: 2026년 3월 31일 | N18: =L18&" ~ "&M18 -> 2025년 4월 1일 ~ 2026년 3월 31일 | O18: iloom7052@hanmail.net
B19: 서산3 | C19: =VLOOKUP(B19,'2503기준유통망'!$B:$F,5,0) -> B/S-Shop | D19: 현금 | E19: 이천만원 | F19: 20,000,000원 | G19: =E19&" (\"&F19&")" -> 이천만원 (\20,000,000원) | H19: =VLOOKUP(B19,계약체결용!$B:$K,7,0) -> 일룸 서산점 | I19: =VLOOKUP(B19,계약체결용!$B:$K,8,0) -> 310-02-95975 | J19: =VLOOKUP(B19,계약체결용!$B:$K,9,0) -> 김 문 자 | K19: =VLOOKUP(B19,계약체결용!$B:$K,10,0) -> 충남 서산시 서해로 3449(석림동) | L19: 2025년 4월 1일 | M19: 2026년 3월 31일 | N19: =L19&" ~ "&M19 -> 2025년 4월 1일 ~ 2026년 3월 31일 | O19: kmj669@hanmail.net
B20: 세종2 | C20: =VLOOKUP(B20,'2503기준유통망'!$B:$F,5,0) -> B/S-Shop | D20: 현금 | E20: 이천만원 | F20: 20,000,000원 | G20: =E20&" (\"&F20&")" -> 이천만원 (\20,000,000원) | H20: =VLOOKUP(B20,계약체결용!$B:$K,7,0) -> 일룸 세종점 | I20: =VLOOKUP(B20,계약체결용!$B:$K,8,0) -> 760-33-00129 | J20: =VLOOKUP(B20,계약체결용!$B:$K,9,0) -> 박정나, 이상연 | K20: =VLOOKUP(B20,계약체결용!$B:$K,10,0) -> 세종 아름동 1313 정원타워 3,4층 | L20: 2025년 4월 1일 | M20: 2026년 3월 31일 | N20: =L20&" ~ "&M20 -> 2025년 4월 1일 ~ 2026년 3월 31일 | O20: iloomsejong2016@daum.net
B21: 수성5 | C21: =VLOOKUP(B21,'2503기준유통망'!$B:$F,5,0) -> B/S-Shop | D21: 현금 | E21: 이천만원 | F21: 20,000,000원 | G21: =E21&" (\"&F21&")" -> 이천만원 (\20,000,000원) | H21: =VLOOKUP(B21,계약체결용!$B:$K,7,0) -> 일룸수성점 | I21: =VLOOKUP(B21,계약체결용!$B:$K,8,0) -> 502-21-75604 | J21: =VLOOKUP(B21,계약체결용!$B:$K,9,0) -> 조진희, 차인호 | K21: =VLOOKUP(B21,계약체결용!$B:$K,10,0) -> 대구 수성구 희망로 152 | L21: 2025년 4월 1일 | M21: 2026년 3월 31일 | N21: =L21&" ~ "&M21 -> 2025년 4월 1일 ~ 2026년 3월 31일 | O21: wlsl4258@hanmail.net
